Workbook

Sheet Summary
A1: Data lineage and record-count reconciliation - independent validation
A2: Counts are live formulas over the 'Checks' sheet (COUNTIF on the status column). INFO rows are observations, not tests.
A4: Status | B4: Checks
A5: PASS | B5: =COUNTIF(Checks!$K$4:$K$118,A5) -> 101
A6: FAIL | B6: =COUNTIF(Checks!$K$4:$K$118,A6) -> 0
A7: BLOCKED | B7: =COUNTIF(Checks!$K$4:$K$118,A7) -> 0
A8: NOT TESTED | B8: =COUNTIF(Checks!$K$4:$K$118,A8) -> 0
A9: INFO | B9: =COUNTIF(Checks!$K$4:$K$118,A9) -> 14
A10: Total | B10: =SUM(B5:B9) -> 115

Sheet Checks
A1: Lineage checks (independent re-derivation from the raw file)
A3: id | B3: area | C3: check | D3: population | E3: definition | F3: expected | G3: actual | H3: abs_diff | I3: rel_diff | J3: tolerance | K3: status | L3: explanation / evidence note | M3: evidence | N3: Recheck |diff| (formula) | O3: Recheck status (formula)
A4: L00 | B4: Data lineage & record reconciliation | C4: Raw CSV SHA-256 equals approved hash | F4: 1 | G4: 1 | H4: 0 | I4: 0 | J4: 0 | K4: PASS | L4: approved a0e6eddde25280aa27a60c5955743d3243b14138d876eedac0547e24a1cc6fff | N4: =IF(AND(ISNUMBER(F4),ISNUMBER(G4)),ABS(G4-F4),"") -> 0 | O4: =IF(AND(ISNUMBER(N4),ISNUMBER(J4)),IF(N4<=J4,"PASS","FAIL"),"n/a") -> PASS
A5: L01 | B5: Data lineage & record reconciliation | C5: Cleaned CSV SHA-256 equals approved hash | F5: 1 | G5: 1 | H5: 0 | I5: 0 | J5: 0 | K5: PASS | L5: approved c184b677bacc6f23086e3b5eedd71836643cb75064e428a1ebfee4c075fa9b47 | N5: =IF(AND(ISNUMBER(F5),ISNUMBER(G5)),ABS(G5-F5),"") -> 0 | O5: =IF(AND(ISNUMBER(N5),ISNUMBER(J5)),IF(N5<=J5,"PASS","FAIL"),"n/a") -> PASS
A6: L02 | B6: Data lineage & record reconciliation | C6: Raw rows | E6: data rows excl. header | F6: 152682 | G6: 152682 | H6: 0 | I6: 0 | J6: 0 | K6: PASS | N6: =IF(AND(ISNUMBER(F6),ISNUMBER(G6)),ABS(G6-F6),"") -> 0 | O6: =IF(AND(ISNUMBER(N6),ISNUMBER(J6)),IF(N6<=J6,"PASS","FAIL"),"n/a") -> PASS
A7: L03 | B7: Data lineage & record reconciliation | C7: Raw columns | F7: 43 | G7: 43 | H7: 0 | I7: 0 | J7: 0 | K7: PASS | N7: =IF(AND(ISNUMBER(F7),ISNUMBER(G7)),ABS(G7-F7),"") -> 0 | O7: =IF(AND(ISNUMBER(N7),ISNUMBER(J7)),IF(N7<=J7,"PASS","FAIL"),"n/a") -> PASS
A8: L04 | B8: Data lineage & record reconciliation | C8: Cleaned rows | F8: 152682 | G8: 152682 | H8: 0 | I8: 0 | J8: 0 | K8: PASS | N8: =IF(AND(ISNUMBER(F8),ISNUMBER(G8)),ABS(G8-F8),"") -> 0 | O8: =IF(AND(ISNUMBER(N8),ISNUMBER(J8)),IF(N8<=J8,"PASS","FAIL"),"n/a") -> PASS
A9: L05 | B9: Data lineage & record reconciliation | C9: Cleaned columns | F9: 192 | G9: 192 | H9: 0 | I9: 0 | J9: 0 | K9: PASS | N9: =IF(AND(ISNUMBER(F9),ISNUMBER(G9)),ABS(G9-F9),"") -> 0 | O9: =IF(AND(ISNUMBER(N9),ISNUMBER(J9)),IF(N9<=J9,"PASS","FAIL"),"n/a") -> PASS
A10: L06 | B10: Data lineage & record reconciliation | C10: Raw row_id unique | F10: 152682 | G10: 152682 | H10: 0 | I10: 0 | J10: 0 | K10: PASS | N10: =IF(AND(ISNUMBER(F10),ISNUMBER(G10)),ABS(G10-F10),"") -> 0 | O10: =IF(AND(ISNUMBER(N10),ISNUMBER(J10)),IF(N10<=J10,"PASS","FAIL"),"n/a") -> PASS
A11: L07 | B11: Data lineage & record reconciliation | C11: Cleaned row_id unique | F11: 152682 | G11: 152682 | H11: 0 | I11: 0 | J11: 0 | K11: PASS | N11: =IF(AND(ISNUMBER(F11),ISNUMBER(G11)),ABS(G11-F11),"") -> 0 | O11: =IF(AND(ISNUMBER(N11),ISNUMBER(J11)),IF(N11<=J11,"PASS","FAIL"),"n/a") -> PASS
A12: L08 | B12: Data lineage & record reconciliation | C12: Raw row_id set == cleaned row_id set (no row lost or added) | E12: symmetric difference of the two id sets | F12: 0 | G12: 0 | H12: 0 | J12: 0 | K12: PASS | N12: =IF(AND(ISNUMBER(F12),ISNUMBER(G12)),ABS(G12-F12),"") -> 0 | O12: =IF(AND(ISNUMBER(N12),ISNUMBER(J12)),IF(N12<=J12,"PASS","FAIL"),"n/a") -> PASS
A13: L09 | B13: Data lineage & record reconciliation | C13: source_row_number = raw file line (row order preserved, 2..152683) | F13: 0 | G13: 0 | H13: 0 | J13: 0 | K13: PASS | N13: =IF(AND(ISNUMBER(F13),ISNUMBER(G13)),ABS(G13-F13),"") -> 0 | O13: =IF(AND(ISNUMBER(N13),ISNUMBER(J13)),IF(N13<=J13,"PASS","FAIL"),"n/a") -> PASS
A14: L10 | B14: Data lineage & record reconciliation | C14: row_id at the same position in raw and cleaned | F14: 0 | G14: 0 | H14: 0 | J14: 0 | K14: PASS | N14: =IF(AND(ISNUMBER(F14),ISNUMBER(G14)),ABS(G14-F14),"") -> 0 | O14: =IF(AND(ISNUMBER(N14),ISNUMBER(J14)),IF(N14<=J14,"PASS","FAIL"),"n/a") -> PASS
A15: L11 | B15: Data lineage & record reconciliation | C15: Exact duplicate rows in raw (all 43 columns) | F15: 0 | G15: 0 | H15: 0 | J15: 0 | K15: PASS | L15: 0 means no fully identical raw records; duplicate CANDIDATES are a separate, unresolved topic | N15: =IF(AND(ISNUMBER(F15),ISNUMBER(G15)),ABS(G15-F15),"") -> 0 | O15: =IF(AND(ISNUMBER(N15),ISNUMBER(J15)),IF(N15<=J15,"PASS","FAIL"),"n/a") -> PASS
A16: L12 | B16: Data lineage & record reconciliation | C16: Cleaned columns that are entirely blank | G16: 0 | K16: INFO | N16: =IF(AND(ISNUMBER(F16),ISNUMBER(G16)),ABS(G16-F16),"") | O16: =IF(AND(ISNUMBER(N16),ISNUMBER(J16)),IF(N16<=J16,"PASS","FAIL"),"n/a") -> n/a
A17: L13.row_id | B17: Data lineage & record reconciliation | C17: Raw value preserved byte-for-byte: row_id -> row_id | F17: 0 | G17: 0 | H17: 0 | J17: 0 | K17: PASS | N17: =IF(AND(ISNUMBER(F17),ISNUMBER(G17)),ABS(G17-F17),"") -> 0 | O17: =IF(AND(ISNUMBER(N17),ISNUMBER(J17)),IF(N17<=J17,"PASS","FAIL"),"n/a") -> PASS
A18: L13.extract_batch | B18: Data lineage & record reconciliation | C18: Raw value preserved byte-for-byte: extract_batch -> extract_batch_raw | F18: 0 | G18: 0 | H18: 0 | J18: 0 | K18: PASS | N18: =IF(AND(ISNUMBER(F18),ISNUMBER(G18)),ABS(G18-F18),"") -> 0 | O18: =IF(AND(ISNUMBER(N18),ISNUMBER(J18)),IF(N18<=J18,"PASS","FAIL"),"n/a") -> PASS
A19: L13.fiscal_year | B19: Data lineage & record reconciliation | C19: Raw value preserved byte-for-byte: fiscal_year -> fiscal_year_raw | F19: 0 | G19: 0 | H19: 0 | J19: 0 | K19: PASS | N19: =IF(AND(ISNUMBER(F19),ISNUMBER(G19)),ABS(G19-F19),"") -> 0 | O19: =IF(AND(ISNUMBER(N19),ISNUMBER(J19)),IF(N19<=J19,"PASS","FAIL"),"n/a") -> PASS
A20: L13.fiscal_period | B20: Data lineage & record reconciliation | C20: Raw value preserved byte-for-byte: fiscal_period -> fiscal_period_raw | F20: 0 | G20: 0 | H20: 0 | J20: 0 | K20: PASS | N20: =IF(AND(ISNUMBER(F20),ISNUMBER(G20)),ABS(G20-F20),"") -> 0 | O20: =IF(AND(ISNUMBER(N20),ISNUMBER(J20)),IF(N20<=J20,"PASS","FAIL"),"n/a") -> PASS
A21: L13.legal_entity | B21: Data lineage & record reconciliation | C21: Raw value preserved byte-for-byte: legal_entity -> legal_entity_raw | F21: 0 | G21: 0 | H21: 0 | J21: 0 | K21: PASS | N21: =IF(AND(ISNUMBER(F21),ISNUMBER(G21)),ABS(G21-F21),"") -> 0 | O21: =IF(AND(ISNUMBER(N21),ISNUMBER(J21)),IF(N21<=J21,"PASS","FAIL"),"n/a") -> PASS
A22: L13.entity_code | B22: Data lineage & record reconciliation | C22: Raw value preserved byte-for-byte: entity_code -> entity_code_raw | F22: 0 | G22: 0 | H22: 0 | J22: 0 | K22: PASS | N22: =IF(AND(ISNUMBER(F22),ISNUMBER(G22)),ABS(G22-F22),"") -> 0 | O22: =IF(AND(ISNUMBER(N22),ISNUMBER(J22)),IF(N22<=J22,"PASS","FAIL"),"n/a") -> PASS
A23: L13.gl_account | B23: Data lineage & record reconciliation | C23: Raw value preserved byte-for-byte: gl_account -> gl_account_raw | F23: 0 | G23: 0 | H23: 0 | J23: 0 | K23: PASS | N23: =IF(AND(ISNUMBER(F23),ISNUMBER(G23)),ABS(G23-F23),"") -> 0 | O23: =IF(AND(ISNUMBER(N23),ISNUMBER(J23)),IF(N23<=J23,"PASS","FAIL"),"n/a") -> PASS
A24: L13.currency | B24: Data lineage & record reconciliation | C24: Raw value preserved byte-for-byte: currency -> currency_raw | F24: 0 | G24: 0 | H24: 0 | J24: 0 | K24: PASS | N24: =IF(AND(ISNUMBER(F24),ISNUMBER(G24)),ABS(G24-F24),"") -> 0 | O24: =IF(AND(ISNUMBER(N24),ISNUMBER(J24)),IF(N24<=J24,"PASS","FAIL"),"n/a") -> PASS
A25: L13.amount_local_raw | B25: Data lineage & record reconciliation | C25: Raw value preserved byte-for-byte: amount_local_raw -> amount_local_raw | F25: 0 | G25: 0 | H25: 0 | J25: 0 | K25: PASS | N25: =IF(AND(ISNUMBER(F25),ISNUMBER(G25)),ABS(G25-F25),"") -> 0 | O25: =IF(AND(ISNUMBER(N25),ISNUMBER(J25)),IF(N25<=J25,"PASS","FAIL"),"n/a") -> PASS
A26: L13.fx_rate_raw | B26: Data lineage & record reconciliation | C26: Raw value preserved byte-for-byte: fx_rate_raw -> fx_rate_raw | F26: 0 | G26: 0 | H26: 0 | J26: 0 | K26: PASS | N26: =IF(AND(ISNUMBER(F26),ISNUMBER(G26)),ABS(G26-F26),"") -> 0 | O26: =IF(AND(ISNUMBER(N26),ISNUMBER(J26)),IF(N26<=J26,"PASS","FAIL"),"n/a") -> PASS
A27: L13.actual_usd_raw | B27: Data lineage & record reconciliation | C27: Raw value preserved byte-for-byte: actual_usd_raw -> actual_usd_raw | F27: 0 | G27: 0 | H27: 0 | J27: 0 | K27: PASS | N27: =IF(AND(ISNUMBER(F27),ISNUMBER(G27)),ABS(G27-F27),"") -> 0 | O27: =IF(AND(ISNUMBER(N27),ISNUMBER(J27)),IF(N27<=J27,"PASS","FAIL"),"n/a") -> PASS
A28: L13.budget_usd_raw | B28: Data lineage & record reconciliation | C28: Raw value preserved byte-for-byte: budget_usd_raw -> budget_usd_raw | F28: 0 | G28: 0 | H28: 0 | J28: 0 | K28: PASS | N28: =IF(AND(ISNUMBER(F28),ISNUMBER(G28)),ABS(G28-F28),"") -> 0 | O28: =IF(AND(ISNUMBER(N28),ISNUMBER(J28)),IF(N28<=J28,"PASS","FAIL"),"n/a") -> PASS
... A35: L13.report_scale | B35: Data lineage & record reconciliation | C35: Raw value preserved byte-for-byte: report_scale -> report_scale_raw | F35: 0 | G35: 0 | H35: 0 | J35: 0 | K35: PASS | N35: =IF(AND(ISNUMBER(F35),ISNUMBER(G35)),ABS(G35-F35),"") -> 0 | O35: =IF(AND(ISNUMBER(N35),ISNUMBER(J35)),IF(N35<=J35,"PASS","FAIL"),"n/a") -> PASS
A36: L14 | B36: Data lineage & record reconciliation | C36: Cleaned (normalised) columns: rows whose value differs from raw | G36: 428020 | K36: INFO | L36: source_system:2038; division:49554; country:0; region:6180; cost_center_code:7405; cost_center_name:7307; cost_center_owner:0; account_name:9004; account_group:3681; fs_line:3747; statement:121962; cost_nature:4510; product_family:0; customer_segment:0; channel:5733; uom:3689; user_id:18689; line_text:21902; intercompany:102625; accrual:7922; elimination_status:30000; scenario_tag:0; approval_status:22072; notes:0 | M36: evidence/work/raw_preservation.csv | N36: =IF(AND(ISNUMBER(F36),ISNUMBER(G36)),ABS(G36-F36),"") | O36: =IF(AND(ISNUMBER(N36),ISNUMBER(J36)),IF(N36<=J36,"PASS","FAIL"),"n/a") -> n/a
A37: L20.amount_local | B37: Data lineage & record reconciliation | C37: Independent raw parse of amount_local: missing/placeholder agreement | E37: placeholders ###, ＃N/A, NA, N/A, n/a, null, -, blank -> missing | F37: 0 | G37: 0 | H37: 0 | J37: 0 | K37: PASS | N37: =IF(AND(ISNUMBER(F37),ISNUMBER(G37)),ABS(G37-F37),"") -> 0 | O37: =IF(AND(ISNUMBER(N37),ISNUMBER(J37)),IF(N37<=J37,"PASS","FAIL"),"n/a") -> PASS
A38: L21.amount_local | B38: Data lineage & record reconciliation | C38: Independent raw parse of amount_local: value agreement (|diff| <= 1e-9) | E38: US 1,234.56 / EU 1.234,56 / decimal comma 54,78 / thousands comma 4,579 / ($) / parentheses negative | F38: 0 | G38: 0 | H38: 0 | J38: 0 | K38: PASS | N38: =IF(AND(ISNUMBER(F38),ISNUMBER(G38)),ABS(G38-F38),"") -> 0 | O38: =IF(AND(ISNUMBER(N38),ISNUMBER(J38)),IF(N38<=J38,"PASS","FAIL"),"n/a") -> PASS
A39: L22.amount_local | B39: Data lineage & record reconciliation | C39: Ambiguous 'n,nnn' strings in amount_local read as thousands (not 3-dp decimal comma) | G39: 9128 | K39: INFO | L39: Same reading as the cleaner. The alternative reading would shrink each value 1000x; no field in the data can settle it. Accepted limitation (disclosed). | N39: =IF(AND(ISNUMBER(F39),ISNUMBER(G39)),ABS(G39-F39),"") | O39: =IF(AND(ISNUMBER(N39),ISNUMBER(J39)),IF(N39<=J39,"PASS","FAIL"),"n/a") -> n/a
A40: L20.actual_usd | B40: Data lineage & record reconciliation | C40: Independent raw parse of actual_usd: missing/placeholder agreement | E40: placeholders ###, ＃N/A, NA, N/A, n/a, null, -, blank -> missing | F40: 0 | G40: 0 | H40: 0 | J40: 0 | K40: PASS | N40: =IF(AND(ISNUMBER(F40),ISNUMBER(G40)),ABS(G40-F40),"") -> 0 | O40: =IF(AND(ISNUMBER(N40),ISNUMBER(J40)),IF(N40<=J40,"PASS","FAIL"),"n/a") -> PASS
A41: L21.actual_usd | B41: Data lineage & record reconciliation | C41: Independent raw parse of actual_usd: value agreement (|diff| <= 1e-9) | E41: US 1,234.56 / EU 1.234,56 / decimal comma 54,78 / thousands comma 4,579 / ($) / parentheses negative | F41: 0 | G41: 0 | H41: 0 | J41: 0 | K41: PASS | N41: =IF(AND(ISNUMBER(F41),ISNUMBER(G41)),ABS(G41-F41),"") -> 0 | O41: =IF(AND(ISNUMBER(N41),ISNUMBER(J41)),IF(N41<=J41,"PASS","FAIL"),"n/a") -> PASS
A42: L22.actual_usd | B42: Data lineage & record reconciliation | C42: Ambiguous 'n,nnn' strings in actual_usd read as thousands (not 3-dp decimal comma) | G42: 9317 | K42: INFO | L42: Same reading as the cleaner. The alternative reading would shrink each value 1000x; no field in the data can settle it. Accepted limitation (disclosed). | N42: =IF(AND(ISNUMBER(F42),ISNUMBER(G42)),ABS(G42-F42),"") | O42: =IF(AND(ISNUMBER(N42),ISNUMBER(J42)),IF(N42<=J42,"PASS","FAIL"),"n/a") -> n/a
A43: L20.budget_usd | B43: Data lineage & record reconciliation | C43: Independent raw parse of budget_usd: missing/placeholder agreement | E43: placeholders ###, ＃N/A, NA, N/A, n/a, null, -, blank -> missing | F43: 0 | G43: 0 | H43: 0 | J43: 0 | K43: PASS | N43: =IF(AND(ISNUMBER(F43),ISNUMBER(G43)),ABS(G43-F43),"") -> 0 | O43: =IF(AND(ISNUMBER(N43),ISNUMBER(J43)),IF(N43<=J43,"PASS","FAIL"),"n/a") -> PASS
A44: L21.budget_usd | B44: Data lineage & record reconciliation | C44: Independent raw parse of budget_usd: value agreement (|diff| <= 1e-9) | E44: US 1,234.56 / EU 1.234,56 / decimal comma 54,78 / thousands comma 4,579 / ($) / parentheses negative | F44: 0 | G44: 0 | H44: 0 | J44: 0 | K44: PASS | N44: =IF(AND(ISNUMBER(F44),ISNUMBER(G44)),ABS(G44-F44),"") -> 0 | O44: =IF(AND(ISNUMBER(N44),ISNUMBER(J44)),IF(N44<=J44,"PASS","FAIL"),"n/a") -> PASS
A45: L22.budget_usd | B45: Data lineage & record reconciliation | C45: Ambiguous 'n,nnn' strings in budget_usd read as thousands (not 3-dp decimal comma) | G45: 9123 | K45: INFO | L45: Same reading as the cleaner. The alternative reading would shrink each value 1000x; no field in the data can settle it. Accepted limitation (disclosed). | N45: =IF(AND(ISNUMBER(F45),ISNUMBER(G45)),ABS(G45-F45),"") | O45: =IF(AND(ISNUMBER(N45),ISNUMBER(J45)),IF(N45<=J45,"PASS","FAIL"),"n/a") -> n/a
A46: L20.forecast_usd | B46: Data lineage & record reconciliation | C46: Independent raw parse of forecast_usd: missing/placeholder agreement | E46: placeholders ###, ＃N/A, NA, N/A, n/a, null, -, blank -> missing | F46: 0 | G46: 0 | H46: 0 | J46: 0 | K46: PASS | N46: =IF(AND(ISNUMBER(F46),ISNUMBER(G46)),ABS(G46-F46),"") -> 0 | O46: =IF(AND(ISNUMBER(N46),ISNUMBER(J46)),IF(N46<=J46,"PASS","FAIL"),"n/a") -> PASS
A47: L21.forecast_usd | B47: Data lineage & record reconciliation | C47: Independent raw parse of forecast_usd: value agreement (|diff| <= 1e-9) | E47: US 1,234.56 / EU 1.234,56 / decimal comma 54,78 / thousands comma 4,579 / ($) / parentheses negative | F47: 0 | G47: 0 | H47: 0 | J47: 0 | K47: PASS | N47: =IF(AND(ISNUMBER(F47),ISNUMBER(G47)),ABS(G47-F47),"") -> 0 | O47: =IF(AND(ISNUMBER(N47),ISNUMBER(J47)),IF(N47<=J47,"PASS","FAIL"),"n/a") -> PASS
...

Sheet Waterfall
A1: Record-count waterfall: raw -> cleaned -> eligibility -> Dashboard populations
A2: Each step is reproducible from the cleaned CSV with the expression in 'identification'; the reasons were re-derived independently from the raw values (check L47).
A3: step | B3: stage | C3: records | D3: note | E3: identification
A4: W00 | B4: Raw records | C4: 152682 | D4: raw CSV data rows | E4: len(raw)
A5: W01 | B5: Cleaned records (1:1 with raw, no row dropped) | C5: 152682 | D5: cleaned CSV rows | E5: L08/L09
A6: W11 | B6: less 1_NON_POSTING_ROW | C6: -350 | D6: remaining 152,332 | E6: excl_PL_actual == '1_NON_POSTING_ROW' (independently re-derived, L47)
A7: W12 | B7: less 2_JUNK_ENTITY | C7: -204 | D7: remaining 152,128 | E7: excl_PL_actual == '2_JUNK_ENTITY' (independently re-derived, L47)
A8: W13 | B8: less 3_ENTITY_UNRESOLVABLE | C8: -16 | D8: remaining 152,112 | E8: excl_PL_actual == '3_ENTITY_UNRESOLVABLE' (independently re-derived, L47)
A9: W14 | B9: less 4_OUT_OF_SCOPE_STATEMENT | C9: -7125 | D9: remaining 144,987 | E9: excl_PL_actual == '4_OUT_OF_SCOPE_STATEMENT' (independently re-derived, L47)
A10: W15 | B10: less 5_STATUS_NOT_ELIGIBLE | C10: -82986 | D10: remaining 62,001 | E10: excl_PL_actual == '5_STATUS_NOT_ELIGIBLE' (independently re-derived, L47)
A11: W16 | B11: less 6_PERIOD_UNRESOLVABLE | C11: 0 | D11: remaining 62,001 | E11: excl_PL_actual == '6_PERIOD_UNRESOLVABLE' (independently re-derived, L47)
A12: W17 | B12: less 7_AMOUNT_MISSING | C12: -3637 | D12: remaining 58,364 | E12: excl_PL_actual == '7_AMOUNT_MISSING' (independently re-derived, L47)
A13: W18 | B13: less 8_SCALE_UNDECIDABLE | C13: -24 | D13: remaining 58,340 | E13: excl_PL_actual == '8_SCALE_UNDECIDABLE' (independently re-derived, L47)
A14: W20 | B14: = Posted eligible P&L lines (dashboard main payload, SQL v_pl_actual) | C14: 58340 | E14: eligible_PL_actual = 1
A15: W30 | B15: Step-5 (status) exclusions | C15: 82986 | E15: excl_PL_actual == 5
A16: W31 | B16: of which also pass steps 6-8 -> non-Posted diagnostic payload | C16: 77990 | E16: v_pl_actual_any_status, status <> Posted
A17: W32 | B17: of which fail step 7 (actual missing) as well -> in NO payload | C17: 4958 | E17: status excl. AND actual missing
A18: W33 | B18: of which fail step 8 (scale undetermined) only -> in NO payload | C18: 38
A19: W40 | B19: Combined dashboard payload | C19: 136330 | E19: P03
A20: W41 | B20: Not in any dashboard payload | C20: 16352 | E20: P04 / gap_16352_breakdown.csv
A21: W50 | B21: P&L variance population (actual AND budget present) | C21: 55043 | E21: eligible_PL_variance = 1
A22: W60 | B22: Balance Sheet actual population (separate, never added to P&L) | C22: 2953 | E22: eligible_BS_actual = 1
A23: W70 | B23: P&L vs forecast population (eligible AND forecast present) | C23: 54851 | E23: v_pl_forecast
A24: W71 | B24: P&L vs prior-year population (eligible AND PY present) | C24: 54923 | E24: v_pl_prior

Sheet Gap_16352
A1: Why 16,352 cleaned rows are in no dashboard population
A2: Posted+non-Posted rows that fail a non-status gate. 0 unexplained rows (check P05).
A3: reason (first failing gate, status gate ignored) | B3: Posted | C3: non-Posted | D3: All
A4: 1_NON_POSTING_ROW | B4: 147 | C4: 203 | D4: 350
A5: 2_JUNK_ENTITY | B5: 90 | C5: 114 | D5: 204
A6: 3_ENTITY_UNRESOLVABLE | B6: 7 | C6: 9 | D6: 16
A7: 4_OUT_OF_SCOPE_STATEMENT (Balance Sheet) | B7: 3136 | C7: 3989 | D7: 7125
A8: 7_AMOUNT_MISSING (actual) | B8: 3637 | C8: 4958 | D8: 8595
A9: 8_SCALE_UNDECIDABLE | B9: 24 | C9: 38 | D9: 62
A10: All | B10: 7041 | C10: 9311 | D10: 16352

Sheet Excl_pl_actual
A1: Primary exclusion reasons - P&L actual (sum must be 152,682)
A3: primary reason | B3: rows
A4: 1_NON_POSTING_ROW | B4: 350
A5: 2_JUNK_ENTITY | B5: 204
A6: 3_ENTITY_UNRESOLVABLE | B6: 16
A7: 4_OUT_OF_SCOPE_STATEMENT | B7: 7125
A8: 5_STATUS_NOT_ELIGIBLE | B8: 82986
A9: 7_AMOUNT_MISSING | B9: 3637
A10: 8_SCALE_UNDECIDABLE | B10: 24
A11: ELIGIBLE | B11: 58340
A12: Total (formula) | B12: =SUM(B4:B11) -> 152682

Sheet Excl_pl_variance
A1: Primary exclusion reasons - P&L variance (actual and budget) (sum must be 152,682)
A3: primary reason | B3: rows
A4: 1_NON_POSTING_ROW | B4: 350
A5: 2_JUNK_ENTITY | B5: 204
A6: 3_ENTITY_UNRESOLVABLE | B6: 16
A7: 4_OUT_OF_SCOPE_STATEMENT | B7: 7125
A8: 5_STATUS_NOT_ELIGIBLE | B8: 82986
A9: 7_AMOUNT_MISSING | B9: 6937
A10: 8_SCALE_UNDECIDABLE | B10: 21
A11: ELIGIBLE | B11: 55043
A12: Total (formula) | B12: =SUM(B4:B11) -> 152682

Sheet Excl_bs_actual
A1: Primary exclusion reasons - Balance Sheet actual (sum must be 152,682)
A3: primary reason | B3: rows
A4: 1_NON_POSTING_ROW | B4: 350
A5: 2_JUNK_ENTITY | B5: 204
A6: 3_ENTITY_UNRESOLVABLE | B6: 16
A7: 4_OUT_OF_SCOPE_STATEMENT | B7: 144987
A8: 5_STATUS_NOT_ELIGIBLE | B8: 3989
A9: 7_AMOUNT_MISSING | B9: 182
A10: 8_SCALE_UNDECIDABLE | B10: 1
A11: ELIGIBLE | B11: 2953
A12: Total (formula) | B12: =SUM(B4:B11) -> 152682

Sheet Raw_preservation
A1: Raw column -> cleaned column: rows whose value differs (raw-value columns must be 0)
A3: raw_column | B3: cleaned_column | C3: rows_differing | D3: note
A4: row_id | B4: row_id | C4: 0
A5: source_system | B5: source_system | C5: 2038
A6: extract_batch | B6: extract_batch_raw | C6: 0
A7: fiscal_year | B7: fiscal_year_raw | C7: 0
A8: fiscal_period | B8: fiscal_period_raw | C8: 0
A9: legal_entity | B9: legal_entity_raw | C9: 0
A10: entity_code | B10: entity_code_raw | C10: 0
A11: division | B11: division | C11: 49554
A12: country | B12: country | C12: 0
A13: region | B13: region | C13: 6180
A14: cost_center_code | B14: cost_center_code | C14: 7405
A15: cost_center_name | B15: cost_center_name | C15: 7307
... A46: notes | B46: notes | C46: 0

Sheet Amount_formats
A1: Raw amount formats found by the independent parser (rows)
A3: format class (independent parser) | B3: amount_local | C3: actual_usd | D3: budget_usd | E3: forecast_usd | F3: prior_year_usd
A4: missing | B4: 9172 | C4: 9259 | D4: 8915 | E4: 9200 | F4: 9069
A5: us | B5: 19436 | C5: 18451 | D5: 18704 | E5: 18611 | F5: 18262
A6: plain | B6: 105724 | C6: 106776 | D6: 107134 | E6: 106963 | F6: 107474
A7: dec_comma | B7: 1389 | C7: 1919 | D7: 1832 | E7: 1817 | F7: 1974
A8: comma_thousands_ambiguous | B8: 9128 | C8: 9317 | D8: 9123 | E8: 9260 | F8: 9058
A9: eu | B9: 7238 | C9: 6936 | D9: 6948 | E9: 6801 | F9: 6826
A10: comma_thousands | B10: 595 | C10: 24 | D10: 26 | E10: 30 | F10: 19
