Workbook

Sheet Start Here
A1: Month-End Close Reliability & Financial Performance Analytics
A2: Phase 5 - FP&A Excel workbook and reconciliation | NovaBridge Industries (synthetic data) | local use only, not published
A4: STATUS: PROVISIONAL. The data is a synthetic extract with unverified provenance and licence. Posted-only eligibility, scale restoration, FX direction and the variance-% convention are working conventions; the account sign convention, duplicate rule and consolidation are unresolved. Read 'Definitions' before quoting any number.
A6: Sheet | B6: What it answers
A7: 1. Start Here | B7: This page: scope, status, navigation, colour legend, source identity.
A8: 2. Executive Summary | B8: Headline numbers, annual view, ranked insights and what the workbook does not claim. All numbers are links.
A9: 3. Monthly P&L | B9: 36-month P&L by section, gross profit, operating result proxy, calendar-year totals, MoM %. Source of the totals every other sheet reconciles to.
A10: 4. Budget vs Actual | B10: Variance by section on same-sign and all-lines bases, bridge, top entity x GL contributors, materiality sensitivity, monthly variance with % check.
A11: 5. Forecast & Prior Year | B11: Forecast error (WAPE, bias), forecast vs budget on matched lines, where the error sits, prior-year column vs true year-on-year.
A12: 6. Entity & Division | B12: Six entities and five divisions: size, margin, variance, growth; entity x GL variance detail.
A13: 7. GL & Cost Drivers | B13: 24 GL accounts, cost Pareto, mix, cost-to-revenue, concentration, persistent deviations, salary-rate scenario (conditional).
A14: 8. Gross Profit | B14: Three explicit discount/sign treatments x two row sets; margin range, versus budget, by entity.
A15: 9. Insights & Actions | B15: Seven ranked insights, 16 fields each: observed vs hypothesis, evidence required, owner, KPI. No savings claims.
A16: 10. Data Quality | B16: Exclusion waterfall (152,682 rows), flag exposure, field reliability, scenario swings, scale/duplicate exposure, balance-sheet limits.
A17: 11. Reconciliation & QA | B17: Live PASS/FAIL formulas: workbook vs independent recompute from the Phase 4 database views, plus source identity.
A18: 12. Definitions | B18: Rules register R1-R14, metric definitions, owner decisions, assumptions, lineage.
A21: Colour and format legend
A22: Blue text | B22: Input value taken from Phase 4 (or an adjustable assumption on an amber cell).
A23: Black text | B23: Formula calculated on the same sheet.
A24: Green text | B24: Formula that links to another sheet in this workbook.
A25: Red text | B25: Link to an external workbook - none exist in this file (checked by the test suite).
A26: Negative numbers | B26: Red in parentheses; zeros show as a dash.
A27: Amber fill | B27: Adjustable threshold, or highlighted result (legend printed on each sheet).
A30: How to read
A31: 1. Amounts: USD, scale-adjusted (provisional), signs as recorded; costs are positive magnitudes.
A32: 2. Variance = Actual - Budget; Variance % = Variance / |net budget|, hidden when |net budget| < 50% of gross budget. Direction columns state arithmetic only.
A33: 3. Primary basis: same-sign lines. The all-lines view is always shown beside it. Opposite-sign and zero-involved lines are bridged, never removed or flipped.
A34: 4. Tables have filters; use the sheet's Basis / Section columns to slice. Every sheet has a link back to this page.
A35: 5. Reconciliation & QA must read ALL CHECKS PASS; if you change an input, re-check it.
A38: Source identity
A39: Reconciliation status | B39: ='Reconciliation & QA'!$B$5 -> ALL 137 CHECKS PASS
A40: Phase 4 database SHA-256 | B40: 00e7437697c8e11baab5d2cff7036d6dda3d251a139774adee0a2dfe92c413e6
A41: Approved cleaned CSV SHA-256 | B41: c184b677bacc6f23086e3b5eedd71836643cb75064e428a1ebfee4c075fa9b47
A42: Generator SHA-256 | B42: 02b45089fc71e6b10d16c738e9796755409290014e85945c80aad932ac564d0a
A43: Generated at (UTC) | B43: 2026-10-29T12:55:33Z
A44: Version | B44: Phase 5 workbook v1.0

Sheet Executive Summary
A1: Executive summary - FP&A month-end close analysis | G1: Back to Start Here
A2: NovaBridge Industries (synthetic extract), Jan 2023 - Dec 2025, six legal entities, USD. Every number on this page is a green link to the sheet that calculates it.
A3: READ FIRST: all figures are provisional. The population is Posted-only journal lines with scale restoration (conventions R6/R7), signs are as recorded (R9 unresolved) and there are no favourable/adverse labels. The operating result proxy is NOT EBITDA. Nothing here is a forecast-skill claim, a saving or a finding about cause - see 'Insights & Actions' for what is observed vs hypothesised.
A5: Headline numbers (3 years, eligible Posted-only lines)
A6: Measure | B6: Value | D6: Where calculated
A7: Revenue (USD) | B7: ='Monthly P&L'!$C$45 -> 2.02649e+08 | D7: Monthly P&L
A8: Gross profit, treatment S1 signed as recorded (USD) | B8: ='Monthly P&L'!$E$45 -> 1.0984098e+08 | D8: Monthly P&L / Gross Profit
A9: Gross margin % (S1) | B9: ='Monthly P&L'!$F$45 -> 0.54202578 | D9: Monthly P&L
A10: Operating result proxy (USD) - not EBITDA | B10: ='Monthly P&L'!$I$45 -> 26319246 | D10: Monthly P&L
A11: Proxy margin % | B11: ='Monthly P&L'!$J$45 -> 0.12987602 | D11: Monthly P&L
A12: Eligible P&L lines (count) | B12: ='Monthly P&L'!$N$45 -> 58340 | D12: Monthly P&L
A13: Revenue growth 2024 vs 2023 | B13: ='Monthly P&L'!$O$52 -> 0.14792168 | D13: Monthly P&L (calendar-year block)
A14: Revenue growth 2025 vs 2024 | B14: ='Monthly P&L'!$O$53 -> 0.0089280979 | D14: Monthly P&L (calendar-year block)
A15: Revenue variance vs budget, same-sign lines (USD) | B15: ='Budget vs Actual'!$E$10 -> -7023037.3 | D15: Budget vs Actual A1
A16: Revenue variance %, same-sign lines | B16: ='Budget vs Actual'!$G$10 -> -0.035574137 | D16: Budget vs Actual A1
A17: COGS variance %, same-sign lines | B17: ='Budget vs Actual'!$G$11 -> 0.064186465 | D17: Budget vs Actual A1
A18: People variance %, same-sign lines | B18: ='Budget vs Actual'!$G$12 -> 0.063740232 | D18: Budget vs Actual A1
A19: Opex variance %, same-sign lines | B19: ='Budget vs Actual'!$G$13 -> 0.064129827 | D19: Budget vs Actual A1
A20: Gross profit variance vs budget, S1 same-sign (USD) | B20: ='Gross Profit'!$H$54 -> -12318779 | D20: Gross Profit GP3
A21: Opposite-sign share of revenue forecast error | B21: ='Forecast & Prior Year'!$F$58 -> 0.91180792 | D21: Forecast & Prior Year F4
A23: Revenue forecast accuracy: three populations, never to be mixed
A24: WAPE = sum |forecast - actual| / sum |actual| (budget analogous). Forecast error = forecast - actual.
A25: Population (revenue lines) | B25: Lines (count) | C25: Forecast WAPE | D25: Budget WAPE | E25: Where calculated
A26: A. Matched same-sign subset: actual, budget and forecast all non-zero with the same sign (selected by outcome) | B26: ='Forecast & Prior Year'!$B$32 -> 24372 | C26: ='Forecast & Prior Year'!$C$32 -> 0.02587993 | D26: ='Forecast & Prior Year'!$D$32 -> 0.03666117 | E26: Forecast & Prior Year F3
A27: B. Comparable lines: actual, budget and forecast all present, any sign (same lines for both measures) | B27: ='Forecast & Prior Year'!$B$49 -> 29131 | C27: ='Forecast & Prior Year'!$C$49 -> 0.268111 | D27: ='Forecast & Prior Year'!$D$49 -> 0.29263818 | E27: Forecast & Prior Year F3b
A28: C. All lines with a forecast value (no budget required; budget WAPE not computed on this population) | B28: ='Forecast & Prior Year'!$B$20 -> 30879 | C28: ='Forecast & Prior Year'!$I$20 -> 0.2659202 | D28: n/a | E28: Forecast & Prior Year F2
A30: Why the populations differ: A keeps only lines where all three amounts agree in sign, which mechanically removes the lines carrying most of the error (opposite-sign lines hold the share of absolute revenue forecast error shown above). B keeps every line that has all three values. C also keeps lines with no budget value.
A31: Reading: the matched-subset WAPE (A) is small because of how the subset is chosen; it is not general forecasting skill. On B both errors are large and the forecast is only modestly closer than the budget for revenue, COGS and opex, and not closer for people costs (see Forecast & Prior Year F3b). The extract has no forecast version or as-of date, so forecast skill cannot be established from either figure.
A34: Reconciliation status (workbook vs independent database recompute) | B34: ='Reconciliation & QA'!$B$5 -> ALL 137 CHECKS PASS
A37: Annual view (links to Monthly P&L)
A38: Year | B38: Revenue (USD) | C38: Gross profit S1 (USD) | D38: Operating result proxy (USD)
A39: 2023 | B39: ='Monthly P&L'!$C$51 -> 61295631 | C39: ='Monthly P&L'!$E$51 -> 32475369 | D39: ='Monthly P&L'!$I$51 -> 5637402.1
A40: 2024 | B40: ='Monthly P&L'!$C$52 -> 70362584 | C40: ='Monthly P&L'!$E$52 -> 40119070 | D40: ='Monthly P&L'!$I$52 -> 11898679
A41: 2025 | B41: ='Monthly P&L'!$C$53 -> 70990788 | C41: ='Monthly P&L'!$E$53 -> 37246545 | D41: ='Monthly P&L'!$I$53 -> 8783165.5
A44: Ranked insights (observed fact first; see 'Insights & Actions' for hypothesis, evidence required, owner and KPI)
A45: Insight | B45: Score (of 12) | C45: Confidence (1-3)
A46: #1 INS-01: The journal-status rule is the largest swing factor in the revenue and result headlines among the four assumptions tested (status, scale, sign, duplicates) | B46: 11 | C46: 2
A47: #2 INS-02: Lines whose forecast and actual have opposite signs (10% to 13% of lines) carry 89% to 91% of the absolute forecast error; whether they are data defects or legitimate entries is unresolved | B47: 11 | C47: 2
A48: #3 INS-03: Actuals sit a near-constant 3.6% below budget on revenue and 6.4% above budget on costs on same-sign lines in all 36 months, all 6 entities, all 5 divisions and every one of the 20 operating accounts (the all-lines view differs) | B48: 10 | C48: 2
A49: #4 INS-04: Gross profit is $12.3M below budget on same-sign lines: 57% of the gap is revenue below budget and 43% is COGS above budget; the margin gap holds under all three discount treatments | B49: 10 | C49: 2
...

Sheet Monthly P&L
A1: Monthly P&L - actuals, Posted-only eligible lines | O1: Back to Start Here
A2: USD, scale-adjusted (provisional), signs as recorded. Source: out_a1_pl_period_section (Phase 4). Costs are positive magnitudes: result = revenue - costs.
A3: Provisional population: Posted-only journal status (rule R6) and the scale-restoration rule are conventions, not confirmed accounting. No favourable/adverse labels: the account sign convention (R9) is unresolved. 'Operating result proxy' = Revenue - COGS - People - Opex; it is NOT EBITDA or operating profit. D&A, below-EBITDA items and tax are shown as memo lines and are not subtotalled because their sign treatment is unverified. Balance-sheet records are excluded (see Data Quality).
A5: MoM highlight threshold (assumption): | D5: 0.1 | E5: <- amber = |month-on-month revenue change| >= threshold (also read the sign in the cell). Blue = input, black = formula.
A7: Month | B7: Year | C7: Revenue (USD) | D7: COGS (USD) | E7: Gross profit, S1 signed as recorded (USD) | F7: Gross margin % (S1) | G7: People costs (USD) | H7: Operating expenses (USD) | I7: Operating result proxy (USD) - not EBITDA | J7: Proxy margin % | K7: Memo: D&A (USD) | L7: Memo: Below-EBITDA (USD) | M7: Memo: Tax (USD) | N7: Eligible lines (count) | O7: Revenue MoM %
A8: 44927 | B8: 2023 | C8: 4261970.3 | D8: 2086530.6 | E8: =C8-D8 -> 2175439.7 | F8: =IF(C8>0,E8/C8,"n/a") -> 0.51043053 | G8: 1300449.4 | H8: 907347.88 | I8: =C8-D8-G8-H8 -> -32357.58 | J8: =IF(C8>0,I8/C8,"n/a") -> -0.0075921645 | K8: 27578.96 | L8: 286.8082 | M8: 102547.78 | N8: 1670 | O8: n/a
A9: 44958 | B9: 2023 | C9: 4952634.8 | D9: 2254535 | E9: =C9-D9 -> 2698099.9 | F9: =IF(C9>0,E9/C9,"n/a") -> 0.5447807 | G9: 989695.09 | H9: 1278087.1 | I9: =C9-D9-G9-H9 -> 430317.64 | J9: =IF(C9>0,I9/C9,"n/a") -> 0.086886608 | K9: 64012.01 | L9: 17800.824 | M9: 76795.04 | N9: 1637 | O9: =IF(C8>0,C9/C8-1,"n/a") -> 0.16205287
A10: 44986 | B10: 2023 | C10: 4520527.3 | D10: 2246171.8 | E10: =C10-D10 -> 2274355.5 | F10: =IF(C10>0,E10/C10,"n/a") -> 0.5031173 | G10: 1227630.7 | H10: 1404752 | I10: =C10-D10-G10-H10 -> -358027.25 | J10: =IF(C10>0,I10/C10,"n/a") -> -0.07920033 | K10: 19335.112 | L10: 20273.621 | M10: 87042.44 | N10: 1598 | O10: =IF(C9>0,C10/C9-1,"n/a") -> -0.087248015
A11: 45017 | B11: 2023 | C11: 5762118.3 | D11: 2506781 | E11: =C11-D11 -> 3255337.2 | F11: =IF(C11>0,E11/C11,"n/a") -> 0.56495495 | G11: 663677.31 | H11: 1182995 | I11: =C11-D11-G11-H11 -> 1408664.9 | J11: =IF(C11>0,I11/C11,"n/a") -> 0.24446998 | K11: 56383.16 | L11: 7004.82 | M11: 75446.31 | N11: 1646 | O11: =IF(C10>0,C11/C10-1,"n/a") -> 0.27465623
A12: 45047 | B12: 2023 | C12: 5278866.6 | D12: 2759484 | E12: =C12-D12 -> 2519382.7 | F12: =IF(C12>0,E12/C12,"n/a") -> 0.47725825 | G12: 920661.37 | H12: 969810.34 | I12: =C12-D12-G12-H12 -> 628910.94 | J12: =IF(C12>0,I12/C12,"n/a") -> 0.11913749 | K12: 89978.81 | L12: 7703.1698 | M12: 76859.84 | N12: 1651 | O12: =IF(C11>0,C12/C11-1,"n/a") -> -0.083867013
A13: 45078 | B13: 2023 | C13: 5344108.5 | D13: 2509076.2 | E13: =C13-D13 -> 2835032.3 | F13: =IF(C13>0,E13/C13,"n/a") -> 0.53049677 | G13: 953553.84 | H13: 908585.81 | I13: =C13-D13-G13-H13 -> 972892.61 | J13: =IF(C13>0,I13/C13,"n/a") -> 0.18204956 | K13: 45497.7 | L13: 12238.169 | M13: 98367.221 | N13: 1605 | O13: =IF(C12>0,C13/C12-1,"n/a") -> 0.012359065
A14: 45108 | B14: 2023 | C14: 6347255 | D14: 2487990.5 | E14: =C14-D14 -> 3859264.4 | F14: =IF(C14>0,E14/C14,"n/a") -> 0.60802102 | G14: 1420978.3 | H14: 1331740.5 | I14: =C14-D14-G14-H14 -> 1106545.6 | J14: =IF(C14>0,I14/C14,"n/a") -> 0.17433452 | K14: 56450.696 | L14: 36953.56 | M14: 114487.94 | N14: 1652 | O14: =IF(C13>0,C14/C13-1,"n/a") -> 0.18771073
A15: 45139 | B15: 2023 | C15: 4916757.8 | D15: 2729906.7 | E15: =C15-D15 -> 2186851 | F15: =IF(C15>0,E15/C15,"n/a") -> 0.44477502 | G15: 1478533.4 | H15: 1252506.4 | I15: =C15-D15-G15-H15 -> -544188.75 | J15: =IF(C15>0,I15/C15,"n/a") -> -0.11068041 | K15: 23719.3 | L15: 20994.469 | M15: 110922.63 | N15: 1644 | O15: =IF(C14>0,C15/C14-1,"n/a") -> -0.22537257
A16: 45170 | B16: 2023 | C16: 5542771.8 | D16: 2149206.5 | E16: =C16-D16 -> 3393565.3 | F16: =IF(C16>0,E16/C16,"n/a") -> 0.61225059 | G16: 1056920.6 | H16: 891852.92 | I16: =C16-D16-G16-H16 -> 1444791.8 | J16: =IF(C16>0,I16/C16,"n/a") -> 0.26066232 | K16: 86655.633 | L16: 28024.181 | M16: 24332.717 | N16: 1580 | O16: =IF(C15>0,C16/C15-1,"n/a") -> 0.12732253
A17: 45200 | B17: 2023 | C17: 4803300.9 | D17: 2128271.6 | E17: =C17-D17 -> 2675029.2 | F17: =IF(C17>0,E17/C17,"n/a") -> 0.55691477 | G17: 1362384.4 | H17: 1200679.9 | I17: =C17-D17-G17-H17 -> 111964.89 | J17: =IF(C17>0,I17/C17,"n/a") -> 0.023309989 | K17: 34374.195 | L17: 12680.771 | M17: 69099.762 | N17: 1630 | O17: =IF(C16>0,C17/C16-1,"n/a") -> -0.13341176
A18: 45231 | B18: 2023 | C18: 4905385.9 | D18: 2495876 | E18: =C18-D18 -> 2409510 | F18: =IF(C18>0,E18/C18,"n/a") -> 0.49119682 | G18: 875813.55 | H18: 1097601.9 | I18: =C18-D18-G18-H18 -> 436094.48 | J18: =IF(C18>0,I18/C18,"n/a") -> 0.088901156 | K18: 21737.31 | L18: 20908.09 | M18: 38621.827 | N18: 1609 | O18: =IF(C17>0,C18/C17-1,"n/a") -> 0.021253106
A19: 45261 | B19: 2023 | C19: 4659933.8 | D19: 2466431.7 | E19: =C19-D19 -> 2193502.2 | F19: =IF(C19>0,E19/C19,"n/a") -> 0.4707153 | G19: 1134455.5 | H19: 1027253.9 | I19: =C19-D19-G19-H19 -> 31792.737 | J19: =IF(C19>0,I19/C19,"n/a") -> 0.0068225726 | K19: 31833.16 | L19: 19408.2 | M19: 110341.38 | N19: 1596 | O19: =IF(C18>0,C19/C18-1,"n/a") -> -0.050037263
A20: 45292 | B20: 2024 | C20: 4879215.5 | D20: 1782755.4 | E20: =C20-D20 -> 3096460 | F20: =IF(C20>0,E20/C20,"n/a") -> 0.63462252 | G20: 1023893.5 | H20: 1132483.4 | I20: =C20-D20-G20-H20 -> 940083.16 | J20: =IF(C20>0,I20/C20,"n/a") -> 0.19267097 | K20: 24064.38 | L20: 23968.43 | M20: 49330.704 | N20: 1603 | O20: =IF(C19>0,C20/C19-1,"n/a") -> 0.047056813
... A43: 45992 | B43: 2025 | C43: 5156931.1 | D43: 2363015.1 | E43: =C43-D43 -> 2793916.1 | F43: =IF(C43>0,E43/C43,"n/a") -> 0.54177882 | G43: 1012075.8 | H43: 1118639.8 | I43: =C43-D43-G43-H43 -> 663200.47 | J43: =IF(C43>0,I43/C43,"n/a") -> 0.12860371 | K43: 42120.64 | L43: 14611.78 | M43: 52438.099 | N43: 1605 | O43: =IF(C42>0,C43/C42-1,"n/a") -> 0.0084184763
A45: Total Jan 2023 - Dec 2025 | C45: =SUM(C8:C43) -> 2.02649e+08 | D45: =SUM(D8:D43) -> 92808018 | E45: =C45-D45 -> 1.0984098e+08 | F45: =IF(C45>0,E45/C45,"n/a") -> 0.54202578 | G45: =SUM(G8:G43) -> 39708939 | H45: =SUM(H8:H43) -> 43812799 | I45: =C45-D45-G45-H45 -> 26319246 | J45: =IF(C45>0,I45/C45,"n/a") -> 0.12987602 | K45: =SUM(K8:K43) -> 1841552.1 | L45: =SUM(L8:L43) -> 595918.87 | M45: =SUM(M8:M43) -> 2751000.7 | N45: =SUM(N8:N43) -> 58340
A48: Calendar-year totals (formulas over the monthly table)
A49: Calendar year of the posting period. Growth = year / prior year - 1.
A50: Year | C50: Revenue (USD) | D50: COGS (USD) | E50: Gross profit S1 (USD) | F50: Gross margin % | G50: People (USD) | H50: Opex (USD) | I50: Operating result proxy (USD) | J50: Proxy margin % | K50: D&A memo (USD) | L50: Below-EBITDA memo (USD) | M50: Tax memo (USD) | N50: Eligible lines | O50: Revenue growth %
A51: 2023 | C51: =SUMIFS($C$8:$C$43,$B$8:$B$43,$A51) -> 61295631 | D51: =SUMIFS($D$8:$D$43,$B$8:$B$43,$A51) -> 28820262 | E51: =C51-D51 -> 32475369 | F51: =IF(C51>0,E51/C51,"n/a") -> 0.5298154 | G51: =SUMIFS($G$8:$G$43,$B$8:$B$43,$A51) -> 13384754 | H51: =SUMIFS($H$8:$H$43,$B$8:$B$43,$A51) -> 13453214 | I51: =C51-D51-G51-H51 -> 5637402.1 | J51: =IF(C51>0,I51/C51,"n/a") -> 0.0919707 | K51: =SUMIFS($K$8:$K$43,$B$8:$B$43,$A51) -> 557556.05 | L51: =SUMIFS($L$8:$L$43,$B$8:$B$43,$A51) -> 204276.68 | M51: =SUMIFS($M$8:$M$43,$B$8:$B$43,$A51) -> 984864.88 | N51: =SUMIFS($N$8:$N$43,$B$8:$B$43,$A51) -> 19518 | O51: n/a
A52: 2024 | C52: =SUMIFS($C$8:$C$43,$B$8:$B$43,$A52) -> 70362584 | D52: =SUMIFS($D$8:$D$43,$B$8:$B$43,$A52) -> 30243513 | E52: =C52-D52 -> 40119070 | F52: =IF(C52>0,E52/C52,"n/a") -> 0.5701762 | G52: =SUMIFS($G$8:$G$43,$B$8:$B$43,$A52) -> 13324774 | H52: =SUMIFS($H$8:$H$43,$B$8:$B$43,$A52) -> 14895617 | I52: =C52-D52-G52-H52 -> 11898679 | J52: =IF(C52>0,I52/C52,"n/a") -> 0.1691052 | K52: =SUMIFS($K$8:$K$43,$B$8:$B$43,$A52) -> 584497.19 | L52: =SUMIFS($L$8:$L$43,$B$8:$B$43,$A52) -> 193094.74 | M52: =SUMIFS($M$8:$M$43,$B$8:$B$43,$A52) -> 765343.56 | N52: =SUMIFS($N$8:$N$43,$B$8:$B$43,$A52) -> 19446 | O52: =C52/C51-1 -> 0.14792168
A53: 2025 | C53: =SUMIFS($C$8:$C$43,$B$8:$B$43,$A53) -> 70990788 | D53: =SUMIFS($D$8:$D$43,$B$8:$B$43,$A53) -> 33744243 | E53: =C53-D53 -> 37246545 | F53: =IF(C53>0,E53/C53,"n/a") -> 0.5246673 | G53: =SUMIFS($G$8:$G$43,$B$8:$B$43,$A53) -> 12999411 | H53: =SUMIFS($H$8:$H$43,$B$8:$B$43,$A53) -> 15463968 | I53: =C53-D53-G53-H53 -> 8783165.5 | J53: =IF(C53>0,I53/C53,"n/a") -> 0.12372261 | K53: =SUMIFS($K$8:$K$43,$B$8:$B$43,$A53) -> 699498.83 | L53: =SUMIFS($L$8:$L$43,$B$8:$B$43,$A53) -> 198547.45 | M53: =SUMIFS($M$8:$M$43,$B$8:$B$43,$A53) -> 1000792.2 | N53: =SUMIFS($N$8:$N$43,$B$8:$B$43,$A53) -> 19376 | O53: =C53/C52-1 -> 0.0089280979

Sheet Budget vs Actual
A1: Budget vs actual | M1: Back to Start Here
A2: USD, scale-adjusted (provisional), signs as recorded. Population: eligible P&L lines that also have a budget (55,043 lines). Sources: out_b1, out_b2, out_b3, out_b4, out_b7-b11.
A3: Definitions follow Phase 4 exactly: Variance = Actual - Budget. Variance % = Variance / |net budget|, published only when |net budget| >= 50% of the gross (absolute) budget (project convention, not an accounting standard). Primary basis = SAME-SIGN lines (actual and budget non-zero with the same sign). 'All lines' includes opposite-sign and zero-involved lines and is shown beside it. Nothing is labelled favourable or unfavourable: the sign convention (R9) is unresolved. Cost-centre variance is not published by Phase 4, so it is not shown.
A5: Net-budget guard (Phase 4 convention): | D5: 0.5 | E5: <- % is shown only when |net budget| / gross budget >= this value. Highlight threshold for |variance %|: | J5: 0.05
A7: A1. By section - SAME-SIGN lines (primary basis)
A8: Gross cell variance = sum of absolute entity x GL x month variances; it shows movements that offset inside the net figure.
A9: Section | B9: Lines (count) | C9: Actual (USD) | D9: Budget (USD) | E9: Net variance = actual - budget (USD) | F9: |Net budget| / gross budget | G9: Variance % of |budget| (guarded) | H9: Gross cell variance (USD) | I9: Gross variance % of gross budget | J9: Direction (arithmetic only)
A10: Revenue | B10: 27537 | C10: 1.9039672e+08 | D10: 1.9741975e+08 | E10: =C10-D10 -> -7023037.3 | F10: 0.97320187 | G10: =IF(AND(F10>=$D$5,D10<>0),E10/ABS(D10),"n/a (guard)") -> -0.035574137 | H10: 7090405 | I10: 0.034952913 | J10: =IF(E10>0,"Actual above budget",IF(E10<0,"Actual below budget","On budget")) -> Actual below budget
A11: COGS | B11: 10142 | C11: 87801326 | D11: 82505584 | E11: =C11-D11 -> 5295741.8 | F11: 0.96416508 | G11: =IF(AND(F11>=$D$5,D11<>0),E11/ABS(D11),"n/a (guard)") -> 0.064186465 | H11: 5490272.1 | I11: 0.064159642 | J11: =IF(E11>0,"Actual above budget",IF(E11<0,"Actual below budget","On budget")) -> Actual above budget
A12: People costs | B12: 2721 | C12: 38264640 | D12: 35971790 | E12: =C12-D12 -> 2292850.2 | F12: 0.98867738 | G12: =IF(AND(F12>=$D$5,D12<>0),E12/ABS(D12),"n/a (guard)") -> 0.063740232 | H12: 2333898 | I12: 0.064146716 | J12: =IF(E12>0,"Actual above budget",IF(E12<0,"Actual below budget","On budget")) -> Actual above budget
A13: Operating expenses | B13: 7125 | C13: 41457348 | D13: 38958919 | E13: =C13-D13 -> 2498428.7 | F13: 0.98175602 | G13: =IF(AND(F13>=$D$5,D13<>0),E13/ABS(D13),"n/a (guard)") -> 0.064129827 | H13: 2564626.6 | I13: 0.064628015 | J13: =IF(E13>0,"Actual above budget",IF(E13<0,"Actual below budget","On budget")) -> Actual above budget
A14: D&A (depreciation, GL 6300) | B14: 292 | C14: 1742110.1 | D14: 1638237.8 | E14: =C14-D14 -> 103872.29 | F14: 0.9287694 | G14: =IF(AND(F14>=$D$5,D14<>0),E14/ABS(D14),"n/a (guard)") -> 0.063404891 | H14: 114022.19 | I14: 0.064642826 | J14: =IF(E14>0,"Actual above budget",IF(E14<0,"Actual below budget","On budget")) -> Actual above budget
A15: Below-EBITDA items | B15: 589 | C15: 525074.46 | D15: 493909.02 | E15: =C15-D15 -> 31165.442 | F15: 0.68097347 | G15: =IF(AND(F15>=$D$5,D15<>0),E15/ABS(D15),"n/a (guard)") -> 0.063099561 | H15: 47619.12 | I15: 0.065654516 | J15: =IF(E15>0,"Actual above budget",IF(E15<0,"Actual below budget","On budget")) -> Actual above budget
A16: Tax | B16: 294 | C16: 2812303.9 | D16: 2645687.7 | E16: =C16-D16 -> 166616.19 | F16: 0.93056576 | G16: =IF(AND(F16>=$D$5,D16<>0),E16/ABS(D16),"n/a (guard)") -> 0.062976513 | H16: 178286.19 | I16: 0.062708467 | J16: =IF(E16>0,"Actual above budget",IF(E16<0,"Actual below budget","On budget")) -> Actual above budget
A19: A2. By section - ALL lines (sensitivity)
A20: Gross cell variance = sum of absolute entity x GL x month variances; it shows movements that offset inside the net figure.
A21: Section | B21: Lines (count) | C21: Actual (USD) | D21: Budget (USD) | E21: Net variance = actual - budget (USD) | F21: |Net budget| / gross budget | G21: Variance % of |budget| (guarded) | H21: Gross cell variance (USD) | I21: Gross variance % of gross budget | J21: Direction (arithmetic only)
A22: Revenue | B22: 30953 | C22: 1.9162786e+08 | D22: 1.9629377e+08 | E22: =C22-D22 -> -4665907.5 | F22: 0.9703321 | G22: =IF(AND(F22>=$D$5,D22<>0),E22/ABS(D22),"n/a (guard)") -> -0.023770023 | H22: 29639085 | I22: 0.14651384 | J22: =IF(E22>0,"Actual above budget",IF(E22<0,"Actual below budget","On budget")) -> Actual below budget
A23: COGS | B23: 11517 | C23: 87563589 | D23: 82756590 | E23: =C23-D23 -> 4806999.4 | F23: 0.94122874 | G23: =IF(AND(F23>=$D$5,D23<>0),E23/ABS(D23),"n/a (guard)") -> 0.058086002 | H23: 18631524 | I23: 0.21190489 | J23: =IF(E23>0,"Actual above budget",IF(E23<0,"Actual below budget","On budget")) -> Actual above budget
A24: People costs | B24: 3101 | C24: 37123068 | D24: 37083624 | E24: =C24-D24 -> 39443.735 | F24: 0.98347432 | G24: =IF(AND(F24>=$D$5,D24<>0),E24/ABS(D24),"n/a (guard)") -> 0.001063643 | H24: 11007528 | I24: 0.29192457 | J24: =IF(E24>0,"Actual above budget",IF(E24<0,"Actual below budget","On budget")) -> Actual above budget
A25: Operating expenses | B25: 8153 | C25: 41160730 | D25: 39236310 | E25: =C25-D25 -> 1924419.9 | F25: 0.96402203 | G25: =IF(AND(F25>=$D$5,D25<>0),E25/ABS(D25),"n/a (guard)") -> 0.049046913 | H25: 13214431 | I25: 0.32467383 | J25: =IF(E25>0,"Actual above budget",IF(E25<0,"Actual below budget","On budget")) -> Actual above budget
A26: D&A (depreciation, GL 6300) | B26: 325 | C26: 1762454.8 | D26: 1621481.1 | E26: =C26-D26 -> 140973.73 | F26: 0.88251888 | G26: =IF(AND(F26>=$D$5,D26<>0),E26/ABS(D26),"n/a (guard)") -> 0.086941336 | H26: 622029.65 | I26: 0.33855031 | J26: =IF(E26>0,"Actual above budget",IF(E26<0,"Actual below budget","On budget")) -> Actual above budget
A27: Below-EBITDA items | B27: 655 | C27: 539704.35 | D27: 481316.27 | E27: =C27-D27 -> 58388.08 | F27: 0.61113906 | G27: =IF(AND(F27>=$D$5,D27<>0),E27/ABS(D27),"n/a (guard)") -> 0.12130917 | H27: 288305.13 | I27: 0.36606809 | J27: =IF(E27>0,"Actual above budget",IF(E27<0,"Actual below budget","On budget")) -> Actual above budget
A28: Tax | B28: 339 | C28: 2715839.9 | D28: 2750950 | E28: =C28-D28 -> -35110.036 | F28: 0.90110569 | G28: =IF(AND(F28>=$D$5,D28<>0),E28/ABS(D28),"n/a (guard)") -> -0.012762877 | H28: 955020.04 | I28: 0.31282793 | J28: =IF(E28>0,"Actual above budget",IF(E28<0,"Actual below budget","On budget")) -> Actual below budget
A31: A3. Bridge: all-lines net variance = same-sign + opposite-sign + zero-involved (out_b8)
A32: Opposite-sign and zero-involved lines are an observation, not a proven error: credit notes, reversals and contra accounts can legitimately differ in sign. They are kept, never flipped or removed.
A33: Section | B33: All lines net variance (USD) | C33: Same-sign (USD) | D33: Opposite-sign (USD) | E33: Zero-involved (USD) | F33: Bridge difference (USD) = all - (same + opposite + zero)
A34: Revenue | B34: -4665907.5 | C34: -7023037.3 | D34: 2361269.7 | E34: -4140 | F34: =B34-(C34+D34+E34) -> -7.4505806e-09
A35: COGS | B35: 4806999.4 | C35: 5295741.8 | D35: -453472.72 | E35: -35269.65 | F35: =B35-(C35+D35+E35) -> -9.3132257e-10
A36: People costs | B36: 39443.735 | C36: 2292850.2 | D36: -2264166.5 | E36: 10760 | F36: =B36-(C36+D36+E36) -> -4.9039954e-09
A37: Operating expenses | B37: 1924419.9 | C37: 2498428.7 | D37: -610688.8 | E37: 36679.92 | F37: =B37-(C37+D37+E37) -> 9.5460564e-09
A38: D&A (depreciation, GL 6300) | B38: 140973.73 | C38: 103872.29 | D38: 37101.44 | E38: 0 | F38: =B38-(C38+D38+E38) -> -2.910383e-11
A39: Below-EBITDA items | B39: 58388.08 | C39: 31165.442 | D39: 27222.637 | E39: 0 | F39: =B39-(C39+D39+E39) -> 0
A40: Tax | B40: -35110.036 | C40: 166616.19 | D40: -217726.22 | E40: 16000 | F40: =B40-(C40+D40+E40) -> -1.0913936e-10
A43: B. Largest entity x GL contributors to the variance - same-sign basis (top 20 by |variance|)
A44: Net variance can hide offsetting cells; 'Share of section gross cell variance' shows each cell's weight against the section's gross movement (Phase 4 out_b2).
A45: Rank by |variance| | B45: Section | C45: Entity | D45: GL | E45: Account | F45: Actual (USD) | G45: Budget (USD) | H45: Variance (USD) | I45: Variance % (Phase 4) | J45: Share of section gross cell variance | K45: Direction (arithmetic only)
A46: 1 | B46: Revenue | C46: US01 | D46: 4100 | E46: Product sales | F46: 45163684 | G46: 46799586 | H46: =F46-G46 -> -1635901.6 | I46: -0.034955471 | J46: 0.23293363 | K46: =IF(H46>0,"Actual above budget",IF(H46<0,"Actual below budget","On budget")) -> Actual below budget
A47: 2 | B47: Revenue | C47: IN01 | D47: 4100 | E47: Product sales | F47: 39062316 | G47: 40431207 | H47: =F47-G47 -> -1368891.5 | I47: -0.0338573 | J47: 0.19491446 | K47: =IF(H47>0,"Actual above budget",IF(H47<0,"Actual below budget","On budget")) -> Actual below budget
A48: 3 | B48: COGS | C48: US01 | D48: 5100 | E48: Materials | F48: 16784899 | G48: 15775213 | H48: =F48-G48 -> 1009686.6 | I48: 0.064004623 | J48: 0.19061869 | K48: =IF(H48>0,"Actual above budget",IF(H48<0,"Actual below budget","On budget")) -> Actual above budget
...

Sheet Forecast & Prior Year
A1: Forecast and prior-year analysis | L1: Back to Start Here
A2: USD, scale-adjusted (provisional), signs as recorded. Forecast error = Forecast - Actual. WAPE = sum|F-A| / sum|A|. Bias = sum(F-A) / sum|A|. Sources: out_c1-c8, out_d1-d5.
A3: THREE DIFFERENT THINGS - do not blur them. (1) Observed: the forecast column differs from actuals by the amounts shown. (2) A historical forecasting-performance measure would need dated forecast snapshots: the extract has NO forecast version or as-of date, so forecast skill, forecast accuracy as a KPI and any bias correction are NOT established here. (3) Business explanations (a late re-forecast, a mechanically derived forecast, planning optimism) are hypotheses. Population: eligible P&L lines with a forecast value; the prior-year COLUMN is not the prior calendar year's actuals (see F6).
A5: F1. Forecast vs actual - SAME-SIGN lines (actual and forecast non-zero, same sign)
A6: Net error = forecast - actual (positive = forecast above actual). Bias and WAPE recomputed from Phase 4 inputs (net error, absolute error and absolute actual).
A7: Section | B7: Lines (count) | C7: Actual (USD) | D7: Forecast (USD) | E7: Net error = forecast - actual (USD) | F7: Absolute error sum (USD) | G7: Absolute actual sum (USD) | H7: Bias = net error / abs actual | I7: WAPE = abs error / abs actual | J7: Observed direction
A8: Revenue | B8: 27593 | C8: 1.9173109e+08 | D8: 1.952144e+08 | E8: =D8-C8 -> 3483312.7 | F8: 5505538.3 | G8: 2.1144577e+08 | H8: =IF(G8>0,E8/G8,"n/a") -> 0.016473787 | I8: =IF(G8>0,F8/G8,"n/a") -> 0.02603759 | J8: =IF(E8>0,"Forecast above actual",IF(E8<0,"Forecast below actual","Equal")) -> Forecast above actual
A9: COGS | B9: 10051 | C9: 87006529 | D9: 84342693 | E9: =D9-C9 -> -2663835.2 | F9: 3600247.2 | G9: 1.0507826e+08 | H9: =IF(G9>0,E9/G9,"n/a") -> -0.025350965 | I9: =IF(G9>0,F9/G9,"n/a") -> 0.034262532 | J9: =IF(E9>0,"Forecast above actual",IF(E9<0,"Forecast below actual","Equal")) -> Forecast below actual
A10: People costs | B10: 2690 | C10: 37742906 | D10: 36607976 | E10: =D10-C10 -> -1134929.4 | F10: 1513623.1 | G10: 44889275 | H10: =IF(G10>0,E10/G10,"n/a") -> -0.025282864 | I10: =IF(G10>0,F10/G10,"n/a") -> 0.033719035 | J10: =IF(E10>0,"Forecast above actual",IF(E10<0,"Forecast below actual","Equal")) -> Forecast below actual
A11: Operating expenses | B11: 7048 | C11: 41408223 | D11: 40141629 | E11: =D11-C11 -> -1266594 | F11: 1703776.8 | G11: 49859051 | H11: =IF(G11>0,E11/G11,"n/a") -> -0.025403491 | I11: =IF(G11>0,F11/G11,"n/a") -> 0.034171866 | J11: =IF(E11>0,"Forecast above actual",IF(E11<0,"Forecast below actual","Equal")) -> Forecast below actual
A12: D&A (depreciation, GL 6300) | B12: 291 | C12: 1706887.7 | D12: 1653528 | E12: =D12-C12 -> -53359.791 | F12: 72067.823 | G12: 2018086.5 | H12: =IF(G12>0,E12/G12,"n/a") -> -0.026440785 | I12: =IF(G12>0,F12/G12,"n/a") -> 0.035710969 | J12: =IF(E12>0,"Forecast above actual",IF(E12<0,"Forecast below actual","Equal")) -> Forecast below actual
A13: Below-EBITDA items | B13: 588 | C13: 573571.01 | D13: 556448.34 | E13: =D13-C13 -> -17122.67 | F13: 31016.526 | G13: 898734.53 | H13: =IF(G13>0,E13/G13,"n/a") -> -0.019051978 | I13: =IF(G13>0,F13/G13,"n/a") -> 0.034511332 | J13: =IF(E13>0,"Forecast above actual",IF(E13<0,"Forecast below actual","Equal")) -> Forecast below actual
A14: Tax | B14: 273 | C14: 2404993 | D14: 2336093.7 | E14: =D14-C14 -> -68899.301 | F14: 95908.071 | G14: 2867875.1 | H14: =IF(G14>0,E14/G14,"n/a") -> -0.024024513 | I14: =IF(G14>0,F14/G14,"n/a") -> 0.033442207 | J14: =IF(E14>0,"Forecast above actual",IF(E14<0,"Forecast below actual","Equal")) -> Forecast below actual
A17: F2. Forecast vs actual - ALL lines
A18: Net error = forecast - actual (positive = forecast above actual). Bias and WAPE recomputed from Phase 4 inputs (net error, absolute error and absolute actual).
A19: Section | B19: Lines (count) | C19: Actual (USD) | D19: Forecast (USD) | E19: Net error = forecast - actual (USD) | F19: Absolute error sum (USD) | G19: Absolute actual sum (USD) | H19: Bias = net error / abs actual | I19: WAPE = abs error / abs actual | J19: Observed direction
A20: Revenue | B20: 30879 | C20: 1.9171908e+08 | D20: 1.952756e+08 | E20: =D20-C20 -> 3556516.2 | F20: 63934715 | G20: 2.4042821e+08 | H20: =IF(G20>0,E20/G20,"n/a") -> 0.014792425 | I20: =IF(G20>0,F20/G20,"n/a") -> 0.2659202 | J20: =IF(E20>0,"Forecast above actual",IF(E20<0,"Forecast below actual","Equal")) -> Forecast above actual
A21: COGS | B21: 11443 | C21: 86904916 | D21: 84491282 | E21: =D21-C21 -> -2413633.4 | F21: 32296581 | G21: 1.1963614e+08 | H21: =IF(G21>0,E21/G21,"n/a") -> -0.020174785 | I21: =IF(G21>0,F21/G21,"n/a") -> 0.26995672 | J21: =IF(E21>0,"Forecast above actual",IF(E21<0,"Forecast below actual","Equal")) -> Forecast below actual
A22: People costs | B22: 3102 | C22: 37478988 | D22: 36857250 | E22: =D22-C22 -> -621737.97 | F22: 15204991 | G22: 51844399 | H22: =IF(G22>0,E22/G22,"n/a") -> -0.011992385 | I22: =IF(G22>0,F22/G22,"n/a") -> 0.29328126 | J22: =IF(E22>0,"Forecast above actual",IF(E22<0,"Forecast below actual","Equal")) -> Forecast below actual
A23: Operating expenses | B23: 8119 | C23: 40927995 | D23: 40599946 | E23: =D23-C23 -> -328049.77 | F23: 15905906 | G23: 57064671 | H23: =IF(G23>0,E23/G23,"n/a") -> -0.0057487368 | I23: =IF(G23>0,F23/G23,"n/a") -> 0.27873473 | J23: =IF(E23>0,"Forecast above actual",IF(E23<0,"Forecast below actual","Equal")) -> Forecast below actual
A24: D&A (depreciation, GL 6300) | B24: 335 | C24: 1739141.3 | D24: 1640330.7 | E24: =D24-C24 -> -98810.641 | F24: 672444.79 | G24: 2329898.3 | H24: =IF(G24>0,E24/G24,"n/a") -> -0.042409852 | I24: =IF(G24>0,F24/G24,"n/a") -> 0.28861551 | J24: =IF(E24>0,"Forecast above actual",IF(E24<0,"Forecast below actual","Equal")) -> Forecast below actual
A25: Below-EBITDA items | B25: 648 | C25: 574242.67 | D25: 554901.34 | E25: =D25-C25 -> -19341.327 | F25: 253860.43 | G25: 1011565.5 | H25: =IF(G25>0,E25/G25,"n/a") -> -0.019120194 | I25: =IF(G25>0,F25/G25,"n/a") -> 0.25095799 | J25: =IF(E25>0,"Forecast above actual",IF(E25<0,"Forecast below actual","Equal")) -> Forecast below actual
A26: Tax | B26: 325 | C26: 2536774.7 | D26: 2204434 | E26: =D26-C26 -> -332340.75 | F26: 1285776.2 | G26: 3471849.7 | H26: =IF(G26>0,E26/G26,"n/a") -> -0.095724407 | I26: =IF(G26>0,F26/G26,"n/a") -> 0.37034327 | J26: =IF(E26>0,"Forecast above actual",IF(E26<0,"Forecast below actual","Equal")) -> Forecast below actual
A29: F3. Is the forecast closer to actuals than the budget? Matched lines only (out_c6)
A30: Same lines for both measures: actual, budget and forecast all non-zero with the same sign. This population is selected by outcome (it drops the opposite-sign lines that carry most of the error - see F4), so the improvement is a statement about these lines only.
A31: Section | B31: Matched lines (count) | C31: WAPE forecast | D31: WAPE budget | E31: Budget WAPE - forecast WAPE (points) | F31: Bias forecast | G31: Bias budget
A32: Revenue | B32: 24372 | C32: 0.02587993 | D32: 0.03666117 | E32: =D32-C32 -> 0.01078124 | F32: 0.016463783 | G32: 0.033897031
A33: COGS | B33: 8837 | C33: 0.034384802 | D33: 0.060005975 | E33: =D33-C33 -> 0.025621173 | F33: -0.025256104 | G33: -0.04970263
A34: People costs | B34: 2370 | C34: 0.033486976 | D34: 0.061206509 | E34: =D34-C34 -> 0.027719533 | F34: -0.024590215 | G34: -0.050526803
A35: Operating expenses | B35: 6186 | C35: 0.034507893 | D35: 0.060635221 | E35: =D35-C35 -> 0.026127328 | F35: -0.025696813 | G35: -0.049884244
A36: D&A (depreciation, GL 6300) | B36: 255 | C36: 0.034698504 | D36: 0.0602104 | E36: =D36-C36 -> 0.025511897 | F36: -0.025123198 | G36: -0.049943047
A37: Below-EBITDA items | B37: 522 | C37: 0.035094038 | D37: 0.061903289 | E37: =D37-C37 -> 0.026809251 | F37: -0.018681925 | G37: -0.035809157
A38: Tax | B38: 245 | C38: 0.033467871 | D38: 0.06064024 | E38: =D38-C38 -> 0.027172369 | F38: -0.025550909 | G38: -0.053044288
A46: F3b. Forecast vs budget on ALL comparable lines (actual, budget and forecast present; any sign)
A47: Same lines for both measures, NOT selected by outcome. Compare with F3: the matched subset drops opposite-sign and zero-involved lines, so its WAPE is much smaller. Neither population establishes forecast skill (no forecast version/as-of date). F2 (all forecast lines) is larger still because it does not require a budget value, so its lines are not the same lines as F3b.
A48: Section | B48: Comparable lines (count) | C48: WAPE forecast | D48: WAPE budget | E48: Forecast WAPE - budget WAPE (points; negative = forecast closer) | F48: Bias forecast | G48: Bias budget
A49: Revenue | B49: 29131 | C49: 0.268111 | D49: 0.29263818 | E49: =C49-D49 -> -0.024527185 | F49: 0.014478934 | G49: 0.019954565
A50: COGS | B50: 10799 | C50: 0.26953264 | D50: 0.29171141 | E50: =C50-D50 -> -0.022178772 | F50: -0.019944454 | G50: -0.040801841
A51: People costs | B51: 2927 | C51: 0.29872398 | D51: 0.29049378 | E51: =C51-D51 -> 0.008230205 | F51: -0.0079038469 | G51: -0.0028601946
A52: Operating expenses | B52: 7647 | C52: 0.27982292 | D52: 0.30221215 | E52: =C52-D52 -> -0.022389233 | F52: -0.0035625417 | G52: -0.029991271
...

Sheet Entity & Division
A1: Entity and division analysis | N1: Back to Start Here
A2: USD, scale-adjusted (provisional), signs as recorded. 3-year totals unless stated. Sources: out_a2, out_a3, out_b2, out_b3, out_g5.
A3: Comparability: all six entities report in USD in this extract after conversion, cover the same 36 months (0 entity-month gaps, out_a6) and use the same Posted-only population. Entity size differs widely, so compare shares and percentages, not raw amounts. Consolidation and intercompany elimination (R12) are unresolved: group totals here are sums of entity lines, not consolidated results.
A5: E1. Actual performance by legal entity (3 years, Posted-only eligible lines)
A6: Gross profit = Revenue - COGS (treatment S1, signed as recorded). Share of group revenue = entity revenue / sum of entity revenues.
A7: Entity | B7: Legal entity | C7: Revenue (USD) | D7: COGS (USD) | E7: Gross profit S1 (USD) | F7: Gross margin % (S1) | G7: People (USD) | H7: Opex (USD) | I7: Operating result proxy (USD) | J7: Proxy margin % | K7: Share of group revenue | L7: Eligible lines (count)
A8: AE01 | B8: NovaBridge MENA FZE | C8: 21148202 | D8: 8731913.5 | E8: =C8-D8 -> 12416288 | F8: =IF(C8>0,E8/C8,"n/a") -> 0.58710847 | G8: 3802070.7 | H8: 4371835 | I8: =C8-D8-G8-H8 -> 4242382.6 | J8: =IF(C8>0,I8/C8,"n/a") -> 0.20060252 | K8: =C8/SUM($C$8:$C$13) -> 0.10435878 | L8: 9634
A9: DE01 | B9: NovaBridge Europe GmbH | C9: 29549094 | D9: 15097025 | E9: =C9-D9 -> 14452069 | F9: =IF(C9>0,E9/C9,"n/a") -> 0.4890867 | G9: 6720387.8 | H9: 6783449 | I9: =C9-D9-G9-H9 -> 948232.08 | J9: =IF(C9>0,I9/C9,"n/a") -> 0.032090056 | K9: =C9/SUM($C$8:$C$13) -> 0.14581416 | L9: 9772
A10: GB01 | B10: NovaBridge UK Ltd | C10: 20503977 | D10: 9747172.4 | E10: =C10-D10 -> 10756805 | F10: =IF(C10>0,E10/C10,"n/a") -> 0.5246204 | G10: 4210720.3 | H10: 4330207.8 | I10: =C10-D10-G10-H10 -> 2215876.5 | J10: =IF(C10>0,I10/C10,"n/a") -> 0.10807057 | K10: =C10/SUM($C$8:$C$13) -> 0.10117976 | L10: 9882
A11: IN01 | B11: NovaBridge India Pvt Ltd | C11: 48348042 | D11: 21648388 | E11: =C11-D11 -> 26699654 | F11: =IF(C11>0,E11/C11,"n/a") -> 0.55223857 | G11: 9134124.4 | H11: 9997788.9 | I11: =C11-D11-G11-H11 -> 7567740.3 | J11: =IF(C11>0,I11/C11,"n/a") -> 0.1565263 | K11: =C11/SUM($C$8:$C$13) -> 0.23858021 | L11: 9692
A12: SG01 | B12: NovaBridge APAC Pte Ltd | C12: 27763849 | D12: 13579996 | E12: =C12-D12 -> 14183853 | F12: =IF(C12>0,E12/C12,"n/a") -> 0.51087487 | G12: 6127320.5 | H12: 6524566.1 | I12: =C12-D12-G12-H12 -> 1531966.2 | J12: =IF(C12>0,I12/C12,"n/a") -> 0.05517845 | K12: =C12/SUM($C$8:$C$13) -> 0.13700462 | L12: 9706
A13: US01 | B13: NovaBridge Americas Inc | C13: 55335838 | D13: 24003522 | E13: =C13-D13 -> 31332316 | F13: =IF(C13>0,E13/C13,"n/a") -> 0.56622105 | G13: 9714315.6 | H13: 11804952 | I13: =C13-D13-G13-H13 -> 9813048.4 | J13: =IF(C13>0,I13/C13,"n/a") -> 0.17733622 | K13: =C13/SUM($C$8:$C$13) -> 0.27306247 | L13: 9654
A14: Group | B14: Sum of entities | C14: =SUM($C$8:$C$13) -> 2.02649e+08 | D14: =SUM($D$8:$D$13) -> 92808018 | G14: =SUM($G$8:$G$13) -> 39708939 | H14: =SUM($H$8:$H$13) -> 43812799 | L14: =SUM($L$8:$L$13) -> 58340
A17: E2. Actual performance by division (3 years)
A18: Division is populated on 100% of eligible lines (out_a5). Shares are of the sum of divisions.
A19: Division | C19: Revenue (USD) | D19: COGS (USD) | E19: Gross profit S1 (USD) | F19: Gross margin % (S1) | G19: People (USD) | H19: Opex (USD) | I19: Operating result proxy (USD) | J19: Proxy margin % | K19: Share of group revenue | L19: Eligible lines (count)
A20: Consumer Durables | C20: 73952684 | D20: 32947623 | E20: =C20-D20 -> 41005061 | F20: =IF(C20>0,E20/C20,"n/a") -> 0.55447699 | G20: 14098554 | H20: 16312049 | I20: =C20-D20-G20-H20 -> 10594458 | J20: =IF(C20>0,I20/C20,"n/a") -> 0.14325996 | K20: =C20/SUM($C$20:$C$24) -> 0.36492992 | L20: 14441
A21: Industrial Components | C21: 51566935 | D21: 23949621 | E21: =C21-D21 -> 27617313 | F21: =IF(C21>0,E21/C21,"n/a") -> 0.53556244 | G21: 11264016 | H21: 11510470 | I21: =C21-D21-G21-H21 -> 4842827.2 | J21: =IF(C21>0,I21/C21,"n/a") -> 0.093913421 | K21: =C21/SUM($C$20:$C$24) -> 0.25446429 | L21: 14598
A22: Medical Devices | C22: 48335023 | D22: 21989480 | E22: =C22-D22 -> 26345542 | F22: =IF(C22>0,E22/C22,"n/a") -> 0.54506114 | G22: 9232766.3 | H22: 9837609.9 | I22: =C22-D22-G22-H22 -> 7275166.2 | J22: =IF(C22>0,I22/C22,"n/a") -> 0.15051542 | K22: =C22/SUM($C$20:$C$24) -> 0.23851597 | L22: 14628
A23: Packaging | C23: 21446251 | D23: 10491725 | E23: =C23-D23 -> 10954526 | F23: =IF(C23>0,E23/C23,"n/a") -> 0.51078981 | G23: 3549153.7 | H23: 4601302 | I23: =C23-D23-G23-H23 -> 2804070.6 | J23: =IF(C23>0,I23/C23,"n/a") -> 0.13074876 | K23: =C23/SUM($C$20:$C$24) -> 0.10582954 | L23: 9713
A24: Services & Spares | C24: 7348110.3 | D24: 3429569.2 | E24: =C24-D24 -> 3918541.1 | F24: =IF(C24>0,E24/C24,"n/a") -> 0.53327195 | G24: 1564449.9 | H24: 1551367.6 | I24: =C24-D24-G24-H24 -> 802723.65 | J24: =IF(C24>0,I24/C24,"n/a") -> 0.10924219 | K24: =C24/SUM($C$20:$C$24) -> 0.036260284 | L24: 4960
A25: Group | C25: =SUM($C$20:$C$24) -> 2.02649e+08
A28: E3. Actual vs budget by legal entity - same-sign basis (SUMIFS over the E6 detail table)
A29: Variance = actual - budget. Variance % = variance / |budget| at entity level; no favourable/adverse label. Cost = COGS + People + Opex.
A30: Entity | B30: Revenue actual (USD) | C30: Revenue budget (USD) | D30: Revenue variance (USD) | E30: Revenue variance % | F30: Cost actual (USD) | G30: Cost budget (USD) | H30: Cost variance (USD) | I30: Cost variance % | J30: Net effect on result proxy (USD) = revenue var - cost var
A31: AE01 | B31: =SUMIFS('Entity & Division'!$G$150:$G$437,'Entity & Division'!$C$150:$C$437,$A31,'Entity & Division'!$A$150:$A$437,"Same-sign",'Entity & Division'!$B$150:$B$437,"REVENUE") -> 19447445 | C31: =SUMIFS('Entity & Division'!$H$150:$H$437,'Entity & Division'!$C$150:$C$437,$A31,'Entity & Division'!$A$150:$A$437,"Same-sign",'Entity & Division'!$B$150:$B$437,"REVENUE") -> 20163398 | D31: =B31-C31 -> -715953 | E31: =IF(C31<>0,D31/ABS(C31),"n/a") -> -0.035507556 | F31: =SUMIFS('Entity & Division'!$G$150:$G$437,'Entity & Division'!$C$150:$C$437,$A31,'Entity & Division'!$A$150:$A$437,"Same-sign",'Entity & Division'!$B$150:$B$437,"COGS")+SUMIFS('Entity & Division'!$G$150:$G$437,'Entity & Division'!$C$150:$C$437,$A31,'Entity & Division'!$A$150:$A$437,"Same-sign",'Entity & Division'!$B$150:$B$437,"PEOPLE")+SUMIFS('Entity & Division'!$G$150:$G$437,'Entity & Division'!$C$150:$C$437,$A31,'Entity & Division'!$A$150:$A$437,"Same-sign",'Entity & Division'!$B$150:$B$437,"OPEX") -> 16521382 | G31: =SUMIFS('Entity & Division'!$H$150:$H$437,'Entity & Division'!$C$150:$C$437,$A31,'Entity & Division'!$A$150:$A$437,"Same-sign",'Entity & Division'!$B$150:$B$437,"COGS")+SUMIFS('Entity & Division'!$H$150:$H$437,'Entity & Division'!$C$150:$C$437,$A31,'Entity & Division'!$A$150:$A$437,"Same-sign",'Entity & Division'!$B$150:$B$437,"PEOPLE")+SUMIFS('Entity & Division'!$H$150:$H$437,'Entity & Division'!$C$150:$C$437,$A31,'Entity & Division'!$A$150:$A$437,"Same-sign",'Entity & Division'!$B$150:$B$437,"OPEX") -> 15523464 | H31: =F31-G31 -> 997918.06 | I31: =IF(G31<>0,H31/ABS(G31),"n/a") -> 0.064284496 | J31: =D31-H31 -> -1713871.1
A32: DE01 | B32: =SUMIFS('Entity & Division'!$G$150:$G$437,'Entity & Division'!$C$150:$C$437,$A32,'Entity & Division'!$A$150:$A$437,"Same-sign",'Entity & Division'!$B$150:$B$437,"REVENUE") -> 27740192 | C32: =SUMIFS('Entity & Division'!$H$150:$H$437,'Entity & Division'!$C$150:$C$437,$A32,'Entity & Division'!$A$150:$A$437,"Same-sign",'Entity & Division'!$B$150:$B$437,"REVENUE") -> 28768945 | D32: =B32-C32 -> -1028752.3 | E32: =IF(C32<>0,D32/ABS(C32),"n/a") -> -0.035759125 | F32: =SUMIFS('Entity & Division'!$G$150:$G$437,'Entity & Division'!$C$150:$C$437,$A32,'Entity & Division'!$A$150:$A$437,"Same-sign",'Entity & Division'!$B$150:$B$437,"COGS")+SUMIFS('Entity & Division'!$G$150:$G$437,'Entity & Division'!$C$150:$C$437,$A32,'Entity & Division'!$A$150:$A$437,"Same-sign",'Entity & Division'!$B$150:$B$437,"PEOPLE")+SUMIFS('Entity & Division'!$G$150:$G$437,'Entity & Division'!$C$150:$C$437,$A32,'Entity & Division'!$A$150:$A$437,"Same-sign",'Entity & Division'!$B$150:$B$437,"OPEX") -> 27067905 | G32: =SUMIFS('Entity & Division'!$H$150:$H$437,'Entity & Division'!$C$150:$C$437,$A32,'Entity & Division'!$A$150:$A$437,"Same-sign",'Entity & Division'!$B$150:$B$437,"COGS")+SUMIFS('Entity & Division'!$H$150:$H$437,'Entity & Division'!$C$150:$C$437,$A32,'Entity & Division'!$A$150:$A$437,"Same-sign",'Entity & Division'!$B$150:$B$437,"PEOPLE")+SUMIFS('Entity & Division'!$H$150:$H$437,'Entity & Division'!$C$150:$C$437,$A32,'Entity & Division'!$A$150:$A$437,"Same-sign",'Entity & Division'!$B$150:$B$437,"OPEX") -> 25427725 | H32: =F32-G32 -> 1640180.1 | I32: =IF(G32<>0,H32/ABS(G32),"n/a") -> 0.064503613 | J32: =D32-H32 -> -2668932.5
A33: GB01 | B33: =SUMIFS('Entity & Division'!$G$150:$G$437,'Entity & Division'!$C$150:$C$437,$A33,'Entity & Division'!$A$150:$A$437,"Same-sign",'Entity & Division'!$B$150:$B$437,"REVENUE") -> 19030287 | C33: =SUMIFS('Entity & Division'!$H$150:$H$437,'Entity & Division'!$C$150:$C$437,$A33,'Entity & Division'!$A$150:$A$437,"Same-sign",'Entity & Division'!$B$150:$B$437,"REVENUE") -> 19723180 | D33: =B33-C33 -> -692893.92 | E33: =IF(C33<>0,D33/ABS(C33),"n/a") -> -0.035130942 | F33: =SUMIFS('Entity & Division'!$G$150:$G$437,'Entity & Division'!$C$150:$C$437,$A33,'Entity & Division'!$A$150:$A$437,"Same-sign",'Entity & Division'!$B$150:$B$437,"COGS")+SUMIFS('Entity & Division'!$G$150:$G$437,'Entity & Division'!$C$150:$C$437,$A33,'Entity & Division'!$A$150:$A$437,"Same-sign",'Entity & Division'!$B$150:$B$437,"PEOPLE")+SUMIFS('Entity & Division'!$G$150:$G$437,'Entity & Division'!$C$150:$C$437,$A33,'Entity & Division'!$A$150:$A$437,"Same-sign",'Entity & Division'!$B$150:$B$437,"OPEX") -> 17487058 | G33: =SUMIFS('Entity & Division'!$H$150:$H$437,'Entity & Division'!$C$150:$C$437,$A33,'Entity & Division'!$A$150:$A$437,"Same-sign",'Entity & Division'!$B$150:$B$437,"COGS")+SUMIFS('Entity & Division'!$H$150:$H$437,'Entity & Division'!$C$150:$C$437,$A33,'Entity & Division'!$A$150:$A$437,"Same-sign",'Entity & Division'!$B$150:$B$437,"PEOPLE")+SUMIFS('Entity & Division'!$H$150:$H$437,'Entity & Division'!$C$150:$C$437,$A33,'Entity & Division'!$A$150:$A$437,"Same-sign",'Entity & Division'!$B$150:$B$437,"OPEX") -> 16444064 | H33: =F33-G33 -> 1042994.6 | I33: =IF(G33<>0,H33/ABS(G33),"n/a") -> 0.063426816 | J33: =D33-H33 -> -1735888.5
A34: IN01 | B34: =SUMIFS('Entity & Division'!$G$150:$G$437,'Entity & Division'!$C$150:$C$437,$A34,'Entity & Division'!$A$150:$A$437,"Same-sign",'Entity & Division'!$B$150:$B$437,"REVENUE") -> 45356329 | C34: =SUMIFS('Entity & Division'!$H$150:$H$437,'Entity & Division'!$C$150:$C$437,$A34,'Entity & Division'!$A$150:$A$437,"Same-sign",'Entity & Division'!$B$150:$B$437,"REVENUE") -> 46995352 | D34: =B34-C34 -> -1639023.1 | E34: =IF(C34<>0,D34/ABS(C34),"n/a") -> -0.034876282 | F34: =SUMIFS('Entity & Division'!$G$150:$G$437,'Entity & Division'!$C$150:$C$437,$A34,'Entity & Division'!$A$150:$A$437,"Same-sign",'Entity & Division'!$B$150:$B$437,"COGS")+SUMIFS('Entity & Division'!$G$150:$G$437,'Entity & Division'!$C$150:$C$437,$A34,'Entity & Division'!$A$150:$A$437,"Same-sign",'Entity & Division'!$B$150:$B$437,"PEOPLE")+SUMIFS('Entity & Division'!$G$150:$G$437,'Entity & Division'!$C$150:$C$437,$A34,'Entity & Division'!$A$150:$A$437,"Same-sign",'Entity & Division'!$B$150:$B$437,"OPEX") -> 38279037 | G34: =SUMIFS('Entity & Division'!$H$150:$H$437,'Entity & Division'!$C$150:$C$437,$A34,'Entity & Division'!$A$150:$A$437,"Same-sign",'Entity & Division'!$B$150:$B$437,"COGS")+SUMIFS('Entity & Division'!$H$150:$H$437,'Entity & Division'!$C$150:$C$437,$A34,'Entity & Division'!$A$150:$A$437,"Same-sign",'Entity & Division'!$B$150:$B$437,"PEOPLE")+SUMIFS('Entity & Division'!$H$150:$H$437,'Entity & Division'!$C$150:$C$437,$A34,'Entity & Division'!$A$150:$A$437,"Same-sign",'Entity & Division'!$B$150:$B$437,"OPEX") -> 35988057 | H34: =F34-G34 -> 2290979.8 | I34: =IF(G34<>0,H34/ABS(G34),"n/a") -> 0.063659446 | J34: =D34-H34 -> -3930002.9
A35: SG01 | B35: =SUMIFS('Entity & Division'!$G$150:$G$437,'Entity & Division'!$C$150:$C$437,$A35,'Entity & Division'!$A$150:$A$437,"Same-sign",'Entity & Division'!$B$150:$B$437,"REVENUE") -> 26567250 | C35: =SUMIFS('Entity & Division'!$H$150:$H$437,'Entity & Division'!$C$150:$C$437,$A35,'Entity & Division'!$A$150:$A$437,"Same-sign",'Entity & Division'!$B$150:$B$437,"REVENUE") -> 27585399 | D35: =B35-C35 -> -1018149.1 | E35: =IF(C35<>0,D35/ABS(C35),"n/a") -> -0.036908984 | F35: =SUMIFS('Entity & Division'!$G$150:$G$437,'Entity & Division'!$C$150:$C$437,$A35,'Entity & Division'!$A$150:$A$437,"Same-sign",'Entity & Division'!$B$150:$B$437,"COGS")+SUMIFS('Entity & Division'!$G$150:$G$437,'Entity & Division'!$C$150:$C$437,$A35,'Entity & Division'!$A$150:$A$437,"Same-sign",'Entity & Division'!$B$150:$B$437,"PEOPLE")+SUMIFS('Entity & Division'!$G$150:$G$437,'Entity & Division'!$C$150:$C$437,$A35,'Entity & Division'!$A$150:$A$437,"Same-sign",'Entity & Division'!$B$150:$B$437,"OPEX") -> 24910282 | G35: =SUMIFS('Entity & Division'!$H$150:$H$437,'Entity & Division'!$C$150:$C$437,$A35,'Entity & Division'!$A$150:$A$437,"Same-sign",'Entity & Division'!$B$150:$B$437,"COGS")+SUMIFS('Entity & Division'!$H$150:$H$437,'Entity & Division'!$C$150:$C$437,$A35,'Entity & Division'!$A$150:$A$437,"Same-sign",'Entity & Division'!$B$150:$B$437,"PEOPLE")+SUMIFS('Entity & Division'!$H$150:$H$437,'Entity & Division'!$C$150:$C$437,$A35,'Entity & Division'!$A$150:$A$437,"Same-sign",'Entity & Division'!$B$150:$B$437,"OPEX") -> 23426054 | H35: =F35-G35 -> 1484227.7 | I35: =IF(G35<>0,H35/ABS(G35),"n/a") -> 0.063357988 | J35: =D35-H35 -> -2502376.7
A36: US01 | B36: =SUMIFS('Entity & Division'!$G$150:$G$437,'Entity & Division'!$C$150:$C$437,$A36,'Entity & Division'!$A$150:$A$437,"Same-sign",'Entity & Division'!$B$150:$B$437,"REVENUE") -> 52255212 | C36: =SUMIFS('Entity & Division'!$H$150:$H$437,'Entity & Division'!$C$150:$C$437,$A36,'Entity & Division'!$A$150:$A$437,"Same-sign",'Entity & Division'!$B$150:$B$437,"REVENUE") -> 54183478 | D36: =B36-C36 -> -1928265.8 | E36: =IF(C36<>0,D36/ABS(C36),"n/a") -> -0.035587708 | F36: =SUMIFS('Entity & Division'!$G$150:$G$437,'Entity & Division'!$C$150:$C$437,$A36,'Entity & Division'!$A$150:$A$437,"Same-sign",'Entity & Division'!$B$150:$B$437,"COGS")+SUMIFS('Entity & Division'!$G$150:$G$437,'Entity & Division'!$C$150:$C$437,$A36,'Entity & Division'!$A$150:$A$437,"Same-sign",'Entity & Division'!$B$150:$B$437,"PEOPLE")+SUMIFS('Entity & Division'!$G$150:$G$437,'Entity & Division'!$C$150:$C$437,$A36,'Entity & Division'!$A$150:$A$437,"Same-sign",'Entity & Division'!$B$150:$B$437,"OPEX") -> 43257650 | G36: =SUMIFS('Entity & Division'!$H$150:$H$437,'Entity & Division'!$C$150:$C$437,$A36,'Entity & Division'!$A$150:$A$437,"Same-sign",'Entity & Division'!$B$150:$B$437,"COGS")+SUMIFS('Entity & Division'!$H$150:$H$437,'Entity & Division'!$C$150:$C$437,$A36,'Entity & Division'!$A$150:$A$437,"Same-sign",'Entity & Division'!$B$150:$B$437,"PEOPLE")+SUMIFS('Entity & Division'!$H$150:$H$437,'Entity & Division'!$C$150:$C$437,$A36,'Entity & Division'!$A$150:$A$437,"Same-sign",'Entity & Division'!$B$150:$B$437,"OPEX") -> 40626930 | H36: =F36-G36 -> 2630720.5 | I36: =IF(G36<>0,H36/ABS(G36),"n/a") -> 0.064753123 | J36: =D36-H36 -> -4558986.4
A41: E4. Actual vs budget by division (out_b3, both bases)
A42: Variance recomputed in Excel (actual - budget); % is the Phase 4 guarded figure.
A43: Basis | B43: Section | C43: Division | D43: Lines (count) | E43: Actual (USD) | F43: Budget (USD) | G43: Variance (USD) | H43: Variance % (Phase 4, guarded)
A44: Same-sign | B44: REVENUE | C44: Consumer Durables | D44: 6824 | E44: 70102762 | F44: 72689502 | G44: =E44-F44 -> -2586740.8 | H44: -0.035586168
A45: Same-sign | B45: REVENUE | C45: Industrial Components | D45: 6832 | E45: 48191424 | F45: 49986088 | G45: =E45-F45 -> -1794664 | H45: -0.03590327
A46: Same-sign | B46: REVENUE | C46: Medical Devices | D46: 6947 | E46: 45390041 | F46: 47055147 | G46: =E46-F46 -> -1665106.1 | H46: -0.035386269
A47: Same-sign | B47: REVENUE | C47: Packaging | D47: 4637 | E47: 19818217 | F47: 20534925 | G47: =E47-F47 -> -716708.72 | H47: -0.03490194
A48: Same-sign | B48: REVENUE | C48: Services & Spares | D48: 2297 | E48: 6894272.6 | F48: 7154090.2 | G48: =E48-F48 -> -259817.59 | H48: -0.036317349
A49: Same-sign | B49: COGS | C49: Consumer Durables | D49: 2482 | E49: 31565327 | F49: 29614684 | G49: =E49-F49 -> 1950643.2 | H49: 0.065867431
...

Sheet GL & Cost Drivers
A1: GL accounts and cost drivers | L1: Back to Start Here
A2: USD, scale-adjusted (provisional), signs as recorded. Sources: out_a4, out_f1-f7, out_b2, out_b6. 3-year totals.
A3: High spending is not proof of inefficiency, and a variance is not a saving. Nothing here claims a causal cost driver. Unit economics (price, volume, mix) are NOT built: quantity is populated on only 33% of revenue lines (UNSUITABLE, out_a5) and the materials unit value equals the sales unit value for every product family (out_e5), so quantity and unit-of-measure fields are unresolved. 'NOS' and 'EA' are not treated as equivalent.
A5: G1. Activity by GL account - all 24 P&L accounts used (out_a4)
A6: Share of total = |actual| / sum of |actual| over all accounts (absolute activity, so offsetting signs do not net out). '% lines negative' flags accounts whose sign convention is mixed (4190 discounts and 5120 PPV are the visible cases).
A7: GL | B7: Account | C7: Section | D7: Eligible lines (count) | E7: Actual, signed (USD) | F7: Absolute actual (USD) | G7: Share of total absolute activity | H7: % of lines negative
A8: 4100 | B8: Product sales | C8: REVENUE | D8: 10989 | E8: 1.7380499e+08 | F8: 2.0290462e+08 | G8: =F8/SUM($F$8:$F$31) -> 0.4014381 | H8: 0.06988807
A9: 4110 | B9: Service and spares revenue | C9: REVENUE | D9: 10619 | E9: 25836278 | F9: 30043878 | G9: =F9/SUM($F$8:$F$31) -> 0.059440527 | H9: 0.070628119
A10: 4120 | B10: Freight recovered | C10: REVENUE | D10: 385 | E10: 5541213.9 | F10: 6200186 | G10: =F10/SUM($F$8:$F$31) -> 0.012266803 | H10: 0.05974026
A11: 4190 | B11: Sales discounts and rebates | C11: REVENUE | D11: 10820 | E11: -2533482.9 | F11: 15381853 | G11: =F11/SUM($F$8:$F$31) -> 0.030432337 | H11: 0.57661738
A12: 5100 | B12: Materials | C12: COGS | D12: 10805 | E12: 66640644 | F12: 90575711 | G12: =F12/SUM($F$8:$F$31) -> 0.17920017 | H12: 0.13216104
A13: 5110 | B13: Inbound freight | C13: COGS | D13: 346 | E13: 5889399.2 | F13: 7867824.6 | G13: =F13/SUM($F$8:$F$31) -> 0.015566154 | H13: 0.12716763
A14: 5120 | B14: Purchase price variance | C14: COGS | D14: 348 | E14: 987251.47 | F14: 2643666 | G14: =F14/SUM($F$8:$F$31) -> 0.0052303799 | H14: 0.33333333
A15: 5200 | B15: Direct labor | C15: COGS | D15: 340 | E15: 11830633 | F15: 15660732 | G15: =F15/SUM($F$8:$F$31) -> 0.030984087 | H15: 0.13529412
A16: 5300 | B16: Factory overhead | C16: COGS | D16: 359 | E16: 7460090.4 | F16: 11251449 | G16: =F16/SUM($F$8:$F$31) -> 0.02226051 | H16: 0.17548747
A17: 6100 | B17: Salaries | C17: PEOPLE | D17: 1071 | E17: 27879880 | F17: 38887948 | G17: =F17/SUM($F$8:$F$31) -> 0.076938139 | H17: 0.13538749
A18: 6110 | B18: Bonus and incentives | C18: PEOPLE | D18: 1133 | E18: 4907347.2 | F18: 6629433.8 | G18: =F18/SUM($F$8:$F$31) -> 0.013116051 | H18: 0.13062665
A19: 6120 | B19: Benefits | C19: PEOPLE | D19: 1081 | E19: 6921711.6 | F19: 9375058.7 | G19: =F19/SUM($F$8:$F$31) -> 0.018548152 | H19: 0.13135985
... A31: 8100 | B31: Income tax expense | C31: TAX | D31: 357 | E31: 2751000.7 | F31: 3786888.1 | G31: =F31/SUM($F$8:$F$31) -> 0.0074921961 | H31: 0.14565826
A32: Total | D32: =SUM($D$8:$D$31) -> 58340 | E32: =SUM($E$8:$E$31) -> 3.8416723e+08 | F32: =SUM($F$8:$F$31) -> 5.0544435e+08
A35: G2. Cost concentration - Pareto of the 17 cost accounts (out_f1)
A36: Cost = COGS + People + Opex + D&A accounts only (COGS 5, D&A 1, OPEX 8, PEOPLE 3), ranked by absolute activity. Below-EBITDA items and Tax are NOT in this population (they are not operating costs and the Phase 4 query excludes them). Cumulative share is a running sum of shares.
A37: Rank | B37: GL | C37: Account | D37: Section | E37: Eligible lines (count) | F37: Actual, signed (USD) | G37: Absolute actual (USD) | H37: Share of cost absolute activity | I37: Cumulative share
A38: 1 | B38: 5100 | C38: Materials | D38: COGS | E38: 10805 | F38: 66640644 | G38: 90575711 | H38: =G38/SUM($G$38:$G$54) -> 0.36812982 | I38: =SUM($H$38:H38) -> 0.36812982
A39: 2 | B39: 6100 | C39: Salaries | D39: PEOPLE | E39: 1071 | F39: 27879880 | G39: 38887948 | H39: =G39/SUM($G$38:$G$54) -> 0.15805356 | I39: =SUM($H$38:H39) -> 0.52618338
A40: 3 | B40: 5200 | C40: Direct labor | D40: COGS | E40: 340 | F40: 11830633 | G40: 15660732 | H40: =G40/SUM($G$38:$G$54) -> 0.063650423 | I40: =SUM($H$38:H40) -> 0.5898338
A41: 4 | B41: 6220 | C41: Warehouse and distribution | D41: OPEX | E41: 1031 | F41: 10084193 | G41: 14039197 | H41: =G41/SUM($G$38:$G$54) -> 0.057059968 | I41: =SUM($H$38:H41) -> 0.64689377
A42: 5 | B42: 6210 | C42: Marketing programs | D42: OPEX | E42: 1086 | F42: 9062846.6 | G42: 11948547 | H42: =G42/SUM($G$38:$G$54) -> 0.048562871 | I42: =SUM($H$38:H42) -> 0.69545664
A43: 6 | B43: 5300 | C43: Factory overhead | D43: COGS | E43: 359 | F43: 7460090.4 | G43: 11251449 | H43: =G43/SUM($G$38:$G$54) -> 0.045729632 | I43: =SUM($H$38:H43) -> 0.74118627
A44: 7 | B44: 6230 | C44: Rent and facilities | D44: OPEX | E44: 1092 | F44: 7324936.6 | G44: 10529962 | H44: =G44/SUM($G$38:$G$54) -> 0.04279727 | I44: =SUM($H$38:H44) -> 0.78398354
A45: 8 | B45: 6120 | C45: Benefits | D45: PEOPLE | E45: 1081 | F45: 6921711.6 | G45: 9375058.7 | H45: =G45/SUM($G$38:$G$54) -> 0.038103357 | I45: =SUM($H$38:H45) -> 0.8220869
A46: 9 | B46: 5110 | C46: Inbound freight | D46: COGS | E46: 346 | F46: 5889399.2 | G46: 7867824.6 | H46: =G46/SUM($G$38:$G$54) -> 0.031977457 | I46: =SUM($H$38:H46) -> 0.85406435
A47: 10 | B47: 6250 | C47: IT and software | D47: OPEX | E47: 1079 | F47: 4769489.4 | G47: 6779051.6 | H47: =G47/SUM($G$38:$G$54) -> 0.027552321 | I47: =SUM($H$38:H47) -> 0.88161668
A48: 11 | B48: 6110 | C48: Bonus and incentives | D48: PEOPLE | E48: 1133 | F48: 4907347.2 | G48: 6629433.8 | H48: =G48/SUM($G$38:$G$54) -> 0.026944225 | I48: =SUM($H$38:H48) -> 0.9085609
