Workbook

Sheet Summary
A1: Financial reconciliation - independent pandas reference vs SQL, Excel and dashboard
A2: Counts are live formulas over the 'Checks' sheet (COUNTIF on the status column). INFO rows are observations, not tests.
A4: Status | B4: Checks
A5: PASS | B5: =COUNTIF(Checks!$K$4:$K$634,A5) -> 620
A6: FAIL | B6: =COUNTIF(Checks!$K$4:$K$634,A6) -> 0
A7: BLOCKED | B7: =COUNTIF(Checks!$K$4:$K$634,A7) -> 0
A8: NOT TESTED | B8: =COUNTIF(Checks!$K$4:$K$634,A8) -> 3
A9: INFO | B9: =COUNTIF(Checks!$K$4:$K$634,A9) -> 8
A10: Total | B10: =SUM(B5:B9) -> 631

Sheet Checks
A1: All financial comparisons (same population, same documented definition on both sides)
A2: Tolerance: money 0.01 USD (one cent); ratios 1e-9; counts exact; dashboard display values at display precision. Table comparisons count the rows outside tolerance (expected 0).
A3: id | B3: area | C3: check | D3: population | E3: definition | F3: expected | G3: actual | H3: abs_diff | I3: rel_diff | J3: tolerance | K3: status | L3: explanation / evidence note | M3: evidence | N3: Recheck |diff| (formula) | O3: Recheck status (formula)
A4: F_A1.keys | B4: Independent financial recomputation vs SQL | C4: P&L by period x section (a1): same key set (rows only in one side) | D4: Posted eligible P&L (58,340) | E4: outer join on period_ym,section | F4: 0 | G4: 0 | H4: 0 | J4: 0 | K4: PASS | N4: =IF(AND(ISNUMBER(F4),ISNUMBER(G4)),ABS(G4-F4),"") -> 0 | O4: =IF(AND(ISNUMBER(N4),ISNUMBER(J4)),IF(N4<=J4,"PASS","FAIL"),"n/a") -> PASS
A5: F_A1.rows_eligible | B5: Independent financial recomputation vs SQL | C5: P&L by period x section (a1): rows_eligible (all 252 rows) | D5: Posted eligible P&L (58,340) | E5: sum of scale-adjusted actual; abs = sum |line| | F5: 0 | G5: 0 | H5: 0 | J5: 0 | K5: PASS | L5: max |SQL - reference| = 0; null-pattern mismatches 0 | N5: =IF(AND(ISNUMBER(F5),ISNUMBER(G5)),ABS(G5-F5),"") -> 0 | O5: =IF(AND(ISNUMBER(N5),ISNUMBER(J5)),IF(N5<=J5,"PASS","FAIL"),"n/a") -> PASS
A6: F_A1.actual_usd | B6: Independent financial recomputation vs SQL | C6: P&L by period x section (a1): actual_usd (all 252 rows) | D6: Posted eligible P&L (58,340) | E6: sum of scale-adjusted actual; abs = sum |line| | F6: 0 | G6: 0 | H6: 0 | J6: 0.01 | K6: PASS | L6: max |SQL - reference| = 9.31e-09; null-pattern mismatches 0 | N6: =IF(AND(ISNUMBER(F6),ISNUMBER(G6)),ABS(G6-F6),"") -> 0 | O6: =IF(AND(ISNUMBER(N6),ISNUMBER(J6)),IF(N6<=J6,"PASS","FAIL"),"n/a") -> PASS
A7: F_A1.abs_actual_usd | B7: Independent financial recomputation vs SQL | C7: P&L by period x section (a1): abs_actual_usd (all 252 rows) | D7: Posted eligible P&L (58,340) | E7: sum of scale-adjusted actual; abs = sum |line| | F7: 0 | G7: 0 | H7: 0 | J7: 0.01 | K7: PASS | L7: max |SQL - reference| = 1.68e-08; null-pattern mismatches 0 | N7: =IF(AND(ISNUMBER(F7),ISNUMBER(G7)),ABS(G7-F7),"") -> 0 | O7: =IF(AND(ISNUMBER(N7),ISNUMBER(J7)),IF(N7<=J7,"PASS","FAIL"),"n/a") -> PASS
A8: F_A1.actual_usd_as_reported_parsed | B8: Independent financial recomputation vs SQL | C8: P&L by period x section (a1): actual_usd_as_reported_parsed (all 252 rows) | D8: Posted eligible P&L (58,340) | E8: sum of scale-adjusted actual; abs = sum |line| | F8: 0 | G8: 0 | H8: 0 | J8: 0.01 | K8: PASS | L8: max |SQL - reference| = 8.38e-09; null-pattern mismatches 0 | N8: =IF(AND(ISNUMBER(F8),ISNUMBER(G8)),ABS(G8-F8),"") -> 0 | O8: =IF(AND(ISNUMBER(N8),ISNUMBER(J8)),IF(N8<=J8,"PASS","FAIL"),"n/a") -> PASS
A9: F_A2.keys | B9: Independent financial recomputation vs SQL | C9: P&L by entity x section (a2): same key set (rows only in one side) | D9: Posted eligible | E9: outer join on entity_code,section | F9: 0 | G9: 0 | H9: 0 | J9: 0 | K9: PASS | N9: =IF(AND(ISNUMBER(F9),ISNUMBER(G9)),ABS(G9-F9),"") -> 0 | O9: =IF(AND(ISNUMBER(N9),ISNUMBER(J9)),IF(N9<=J9,"PASS","FAIL"),"n/a") -> PASS
A10: F_A2.rows_eligible | B10: Independent financial recomputation vs SQL | C10: P&L by entity x section (a2): rows_eligible (all 42 rows) | D10: Posted eligible | F10: 0 | G10: 0 | H10: 0 | J10: 0 | K10: PASS | L10: max |SQL - reference| = 0; null-pattern mismatches 0 | N10: =IF(AND(ISNUMBER(F10),ISNUMBER(G10)),ABS(G10-F10),"") -> 0 | O10: =IF(AND(ISNUMBER(N10),ISNUMBER(J10)),IF(N10<=J10,"PASS","FAIL"),"n/a") -> PASS
A11: F_A2.actual_usd | B11: Independent financial recomputation vs SQL | C11: P&L by entity x section (a2): actual_usd (all 42 rows) | D11: Posted eligible | F11: 0 | G11: 0 | H11: 0 | J11: 0.01 | K11: PASS | L11: max |SQL - reference| = 1.27e-07; null-pattern mismatches 0 | N11: =IF(AND(ISNUMBER(F11),ISNUMBER(G11)),ABS(G11-F11),"") -> 0 | O11: =IF(AND(ISNUMBER(N11),ISNUMBER(J11)),IF(N11<=J11,"PASS","FAIL"),"n/a") -> PASS
A12: F_A2.abs_actual_usd | B12: Independent financial recomputation vs SQL | C12: P&L by entity x section (a2): abs_actual_usd (all 42 rows) | D12: Posted eligible | F12: 0 | G12: 0 | H12: 0 | J12: 0.01 | K12: PASS | L12: max |SQL - reference| = 9.69e-08; null-pattern mismatches 0 | N12: =IF(AND(ISNUMBER(F12),ISNUMBER(G12)),ABS(G12-F12),"") -> 0 | O12: =IF(AND(ISNUMBER(N12),ISNUMBER(J12)),IF(N12<=J12,"PASS","FAIL"),"n/a") -> PASS
A13: F_A2.share_of_section_abs | B13: Independent financial recomputation vs SQL | C13: P&L by entity x section (a2): share_of_section_abs (all 42 rows) | D13: Posted eligible | F13: 0 | G13: 0 | H13: 0 | J13: 1e-09 | K13: PASS | L13: max |SQL - reference| = 3.89e-16; null-pattern mismatches 0 | N13: =IF(AND(ISNUMBER(F13),ISNUMBER(G13)),ABS(G13-F13),"") -> 0 | O13: =IF(AND(ISNUMBER(N13),ISNUMBER(J13)),IF(N13<=J13,"PASS","FAIL"),"n/a") -> PASS
A14: F_A3.keys | B14: Independent financial recomputation vs SQL | C14: P&L by division x section (a3): same key set (rows only in one side) | D14: Posted eligible | E14: outer join on division,section | F14: 0 | G14: 0 | H14: 0 | J14: 0 | K14: PASS | N14: =IF(AND(ISNUMBER(F14),ISNUMBER(G14)),ABS(G14-F14),"") -> 0 | O14: =IF(AND(ISNUMBER(N14),ISNUMBER(J14)),IF(N14<=J14,"PASS","FAIL"),"n/a") -> PASS
A15: F_A3.rows_eligible | B15: Independent financial recomputation vs SQL | C15: P&L by division x section (a3): rows_eligible (all 35 rows) | D15: Posted eligible | F15: 0 | G15: 0 | H15: 0 | J15: 0 | K15: PASS | L15: max |SQL - reference| = 0; null-pattern mismatches 0 | N15: =IF(AND(ISNUMBER(F15),ISNUMBER(G15)),ABS(G15-F15),"") -> 0 | O15: =IF(AND(ISNUMBER(N15),ISNUMBER(J15)),IF(N15<=J15,"PASS","FAIL"),"n/a") -> PASS
A16: F_A3.actual_usd | B16: Independent financial recomputation vs SQL | C16: P&L by division x section (a3): actual_usd (all 35 rows) | D16: Posted eligible | F16: 0 | G16: 0 | H16: 0 | J16: 0.01 | K16: PASS | L16: max |SQL - reference| = 2.24e-07; null-pattern mismatches 0 | N16: =IF(AND(ISNUMBER(F16),ISNUMBER(G16)),ABS(G16-F16),"") -> 0 | O16: =IF(AND(ISNUMBER(N16),ISNUMBER(J16)),IF(N16<=J16,"PASS","FAIL"),"n/a") -> PASS
A17: F_A3.abs_actual_usd | B17: Independent financial recomputation vs SQL | C17: P&L by division x section (a3): abs_actual_usd (all 35 rows) | D17: Posted eligible | F17: 0 | G17: 0 | H17: 0 | J17: 0.01 | K17: PASS | L17: max |SQL - reference| = 2.01e-07; null-pattern mismatches 0 | N17: =IF(AND(ISNUMBER(F17),ISNUMBER(G17)),ABS(G17-F17),"") -> 0 | O17: =IF(AND(ISNUMBER(N17),ISNUMBER(J17)),IF(N17<=J17,"PASS","FAIL"),"n/a") -> PASS
A18: F_A3.share_of_section_abs | B18: Independent financial recomputation vs SQL | C18: P&L by division x section (a3): share_of_section_abs (all 35 rows) | D18: Posted eligible | F18: 0 | G18: 0 | H18: 0 | J18: 1e-09 | K18: PASS | L18: max |SQL - reference| = 8.33e-16; null-pattern mismatches 0 | N18: =IF(AND(ISNUMBER(F18),ISNUMBER(G18)),ABS(G18-F18),"") -> 0 | O18: =IF(AND(ISNUMBER(N18),ISNUMBER(J18)),IF(N18<=J18,"PASS","FAIL"),"n/a") -> PASS
A19: F_A4.keys | B19: Independent financial recomputation vs SQL | C19: P&L by GL account (a4): same key set (rows only in one side) | D19: Posted eligible | E19: outer join on gl_account | F19: 0 | G19: 0 | H19: 0 | J19: 0 | K19: PASS | N19: =IF(AND(ISNUMBER(F19),ISNUMBER(G19)),ABS(G19-F19),"") -> 0 | O19: =IF(AND(ISNUMBER(N19),ISNUMBER(J19)),IF(N19<=J19,"PASS","FAIL"),"n/a") -> PASS
A20: F_A4.rows_eligible | B20: Independent financial recomputation vs SQL | C20: P&L by GL account (a4): rows_eligible (all 24 rows) | D20: Posted eligible | F20: 0 | G20: 0 | H20: 0 | J20: 0 | K20: PASS | L20: max |SQL - reference| = 0; null-pattern mismatches 0 | N20: =IF(AND(ISNUMBER(F20),ISNUMBER(G20)),ABS(G20-F20),"") -> 0 | O20: =IF(AND(ISNUMBER(N20),ISNUMBER(J20)),IF(N20<=J20,"PASS","FAIL"),"n/a") -> PASS
A21: F_A4.actual_usd | B21: Independent financial recomputation vs SQL | C21: P&L by GL account (a4): actual_usd (all 24 rows) | D21: Posted eligible | F21: 0 | G21: 0 | H21: 0 | J21: 0.01 | K21: PASS | L21: max |SQL - reference| = 1.07e-06; null-pattern mismatches 0 | N21: =IF(AND(ISNUMBER(F21),ISNUMBER(G21)),ABS(G21-F21),"") -> 0 | O21: =IF(AND(ISNUMBER(N21),ISNUMBER(J21)),IF(N21<=J21,"PASS","FAIL"),"n/a") -> PASS
A22: F_A4.abs_actual_usd | B22: Independent financial recomputation vs SQL | C22: P&L by GL account (a4): abs_actual_usd (all 24 rows) | D22: Posted eligible | F22: 0 | G22: 0 | H22: 0 | J22: 0.01 | K22: PASS | L22: max |SQL - reference| = 5.96e-07; null-pattern mismatches 0 | N22: =IF(AND(ISNUMBER(F22),ISNUMBER(G22)),ABS(G22-F22),"") -> 0 | O22: =IF(AND(ISNUMBER(N22),ISNUMBER(J22)),IF(N22<=J22,"PASS","FAIL"),"n/a") -> PASS
A23: F_A4.share_of_total_abs | B23: Independent financial recomputation vs SQL | C23: P&L by GL account (a4): share_of_total_abs (all 24 rows) | D23: Posted eligible | F23: 0 | G23: 0 | H23: 0 | J23: 1e-09 | K23: PASS | L23: max |SQL - reference| = 9.99e-16; null-pattern mismatches 0 | N23: =IF(AND(ISNUMBER(F23),ISNUMBER(G23)),ABS(G23-F23),"") -> 0 | O23: =IF(AND(ISNUMBER(N23),ISNUMBER(J23)),IF(N23<=J23,"PASS","FAIL"),"n/a") -> PASS
A24: F_A4.share_rows_negative | B24: Independent financial recomputation vs SQL | C24: P&L by GL account (a4): share_rows_negative (all 24 rows) | D24: Posted eligible | F24: 0 | G24: 0 | H24: 0 | J24: 1e-09 | K24: PASS | L24: max |SQL - reference| = 9.71e-17; null-pattern mismatches 0 | N24: =IF(AND(ISNUMBER(F24),ISNUMBER(G24)),ABS(G24-F24),"") -> 0 | O24: =IF(AND(ISNUMBER(N24),ISNUMBER(J24)),IF(N24<=J24,"PASS","FAIL"),"n/a") -> PASS
A25: F_B0 | B25: Independent financial recomputation vs SQL | C25: Variance population rows (Posted eligible with budget) | F25: 55043 | G25: 55043 | H25: 0 | I25: 0 | J25: 0 | K25: PASS | N25: =IF(AND(ISNUMBER(F25),ISNUMBER(G25)),ABS(G25-F25),"") -> 0 | O25: =IF(AND(ISNUMBER(N25),ISNUMBER(J25)),IF(N25<=J25,"PASS","FAIL"),"n/a") -> PASS
A26: F_B1.keys | B26: Independent financial recomputation vs SQL | C26: Budget variance by section, 4 sign scenarios (b1): same key set (rows only in one side) | D26: Posted eligible with budget (55,043) | E26: outer join on scenario,section | F26: 0 | G26: 0 | H26: 0 | J26: 0 | K26: PASS | N26: =IF(AND(ISNUMBER(F26),ISNUMBER(G26)),ABS(G26-F26),"") -> 0 | O26: =IF(AND(ISNUMBER(N26),ISNUMBER(J26)),IF(N26<=J26,"PASS","FAIL"),"n/a") -> PASS
A27: F_B1.rows_in_scope | B27: Independent financial recomputation vs SQL | C27: Budget variance by section, 4 sign scenarios (b1): rows_in_scope (all 26 rows) | D27: Posted eligible with budget (55,043) | E27: variance = actual - budget; pct guarded: |net budget| >= 50% of sum |cell budget| | F27: 0 | G27: 0 | H27: 0 | J27: 0 | K27: PASS | L27: max |SQL - reference| = 0; null-pattern mismatches 0 | N27: =IF(AND(ISNUMBER(F27),ISNUMBER(G27)),ABS(G27-F27),"") -> 0 | O27: =IF(AND(ISNUMBER(N27),ISNUMBER(J27)),IF(N27<=J27,"PASS","FAIL"),"n/a") -> PASS
A28: F_B1.actual_usd | B28: Independent financial recomputation vs SQL | C28: Budget variance by section, 4 sign scenarios (b1): actual_usd (all 26 rows) | D28: Posted eligible with budget (55,043) | E28: variance = actual - budget; pct guarded: |net budget| >= 50% of sum |cell budget| | F28: 0 | G28: 0 | H28: 0 | J28: 0.01 | K28: PASS | L28: max |SQL - reference| = 3.87e-07; null-pattern mismatches 0 | N28: =IF(AND(ISNUMBER(F28),ISNUMBER(G28)),ABS(G28-F28),"") -> 0 | O28: =IF(AND(ISNUMBER(N28),ISNUMBER(J28)),IF(N28<=J28,"PASS","FAIL"),"n/a") -> PASS
A29: F_B1.budget_usd | B29: Independent financial recomputation vs SQL | C29: Budget variance by section, 4 sign scenarios (b1): budget_usd (all 26 rows) | D29: Posted eligible with budget (55,043) | E29: variance = actual - budget; pct guarded: |net budget| >= 50% of sum |cell budget| | F29: 0 | G29: 0 | H29: 0 | J29: 0.01 | K29: PASS | L29: max |SQL - reference| = 2.09e-07; null-pattern mismatches 0 | N29: =IF(AND(ISNUMBER(F29),ISNUMBER(G29)),ABS(G29-F29),"") -> 0 | O29: =IF(AND(ISNUMBER(N29),ISNUMBER(J29)),IF(N29<=J29,"PASS","FAIL"),"n/a") -> PASS
A30: F_B1.net_variance_usd | B30: Independent financial recomputation vs SQL | C30: Budget variance by section, 4 sign scenarios (b1): net_variance_usd (all 26 rows) | D30: Posted eligible with budget (55,043) | E30: variance = actual - budget; pct guarded: |net budget| >= 50% of sum |cell budget| | F30: 0 | G30: 0 | H30: 0 | J30: 0.01 | K30: PASS | L30: max |SQL - reference| = 8.85e-09; null-pattern mismatches 0 | N30: =IF(AND(ISNUMBER(F30),ISNUMBER(G30)),ABS(G30-F30),"") -> 0 | O30: =IF(AND(ISNUMBER(N30),ISNUMBER(J30)),IF(N30<=J30,"PASS","FAIL"),"n/a") -> PASS
A31: F_B1.gross_cell_variance_usd | B31: Independent financial recomputation vs SQL | C31: Budget variance by section, 4 sign scenarios (b1): gross_cell_variance_usd (all 26 rows) | D31: Posted eligible with budget (55,043) | E31: variance = actual - budget; pct guarded: |net budget| >= 50% of sum |cell budget| | F31: 0 | G31: 0 | H31: 0 | J31: 0.01 | K31: PASS | L31: max |SQL - reference| = 2.98e-08; null-pattern mismatches 0 | N31: =IF(AND(ISNUMBER(F31),ISNUMBER(G31)),ABS(G31-F31),"") -> 0 | O31: =IF(AND(ISNUMBER(N31),ISNUMBER(J31)),IF(N31<=J31,"PASS","FAIL"),"n/a") -> PASS
A32: F_B1.variance_pct_of_abs_budget | B32: Independent financial recomputation vs SQL | C32: Budget variance by section, 4 sign scenarios (b1): variance_pct_of_abs_budget (all 26 rows) | D32: Posted eligible with budget (55,043) | E32: variance = actual - budget; pct guarded: |net budget| >= 50% of sum |cell budget| | F32: 0 | G32: 0 | H32: 0 | J32: 1e-09 | K32: PASS | L32: max |SQL - reference| = 3.05e-16; null-pattern mismatches 0 | N32: =IF(AND(ISNUMBER(F32),ISNUMBER(G32)),ABS(G32-F32),"") -> 0 | O32: =IF(AND(ISNUMBER(N32),ISNUMBER(J32)),IF(N32<=J32,"PASS","FAIL"),"n/a") -> PASS
A33: F_B1.budget_netting_ratio | B33: Independent financial recomputation vs SQL | C33: Budget variance by section, 4 sign scenarios (b1): budget_netting_ratio (all 26 rows) | D33: Posted eligible with budget (55,043) | E33: variance = actual - budget; pct guarded: |net budget| >= 50% of sum |cell budget| | F33: 0 | G33: 0 | H33: 0 | J33: 1e-09 | K33: PASS | L33: max |SQL - reference| = 1.89e-15; null-pattern mismatches 0 | N33: =IF(AND(ISNUMBER(F33),ISNUMBER(G33)),ABS(G33-F33),"") -> 0 | O33: =IF(AND(ISNUMBER(N33),ISNUMBER(J33)),IF(N33<=J33,"PASS","FAIL"),"n/a") -> PASS
A34: F_B1.gross_variance_pct_of_abs_cell_budget | B34: Independent financial recomputation vs SQL | C34: Budget variance by section, 4 sign scenarios (b1): gross_variance_pct_of_abs_cell_budget (all 26 rows) | D34: Posted eligible with budget (55,043) | E34: variance = actual - budget; pct guarded: |net budget| >= 50% of sum |cell budget| | F34: 0 | G34: 0 | H34: 0 | J34: 1e-09 | K34: PASS | L34: max |SQL - reference| = 2.22e-15; null-pattern mismatches 0 | N34: =IF(AND(ISNUMBER(F34),ISNUMBER(G34)),ABS(G34-F34),"") -> 0 | O34: =IF(AND(ISNUMBER(N34),ISNUMBER(J34)),IF(N34<=J34,"PASS","FAIL"),"n/a") -> PASS
A35: F_B3.keys | B35: Independent financial recomputation vs SQL | C35: Budget variance by division x section (b3, amounts): same key set (rows only in one side) | D35: Posted eligible with budget | E35: outer join on scenario,division,section | F35: 0 | G35: 0 | H35: 0 | J35: 0 | K35: PASS | N35: =IF(AND(ISNUMBER(F35),ISNUMBER(G35)),ABS(G35-F35),"") -> 0 | O35: =IF(AND(ISNUMBER(N35),ISNUMBER(J35)),IF(N35<=J35,"PASS","FAIL"),"n/a") -> PASS
A36: F_B3.rows_in_scope | B36: Independent financial recomputation vs SQL | C36: Budget variance by division x section (b3, amounts): rows_in_scope (all 70 rows) | D36: Posted eligible with budget | F36: 0 | G36: 0 | H36: 0 | J36: 0 | K36: PASS | L36: max |SQL - reference| = 0; null-pattern mismatches 0 | N36: =IF(AND(ISNUMBER(F36),ISNUMBER(G36)),ABS(G36-F36),"") -> 0 | O36: =IF(AND(ISNUMBER(N36),ISNUMBER(J36)),IF(N36<=J36,"PASS","FAIL"),"n/a") -> PASS
A37: F_B3.actual_usd | B37: Independent financial recomputation vs SQL | C37: Budget variance by division x section (b3, amounts): actual_usd (all 70 rows) | D37: Posted eligible with budget | F37: 0 | G37: 0 | H37: 0 | J37: 0.01 | K37: PASS | L37: max |SQL - reference| = 1.94e-07; null-pattern mismatches 0 | N37: =IF(AND(ISNUMBER(F37),ISNUMBER(G37)),ABS(G37-F37),"") -> 0 | O37: =IF(AND(ISNUMBER(N37),ISNUMBER(J37)),IF(N37<=J37,"PASS","FAIL"),"n/a") -> PASS
A38: F_B3.budget_usd | B38: Independent financial recomputation vs SQL | C38: Budget variance by division x section (b3, amounts): budget_usd (all 70 rows) | D38: Posted eligible with budget | F38: 0 | G38: 0 | H38: 0 | J38: 0.01 | K38: PASS | L38: max |SQL - reference| = 9.69e-08; null-pattern mismatches 0 | N38: =IF(AND(ISNUMBER(F38),ISNUMBER(G38)),ABS(G38-F38),"") -> 0 | O38: =IF(AND(ISNUMBER(N38),ISNUMBER(J38)),IF(N38<=J38,"PASS","FAIL"),"n/a") -> PASS
A39: F_B3.variance_usd | B39: Independent financial recomputation vs SQL | C39: Budget variance by division x section (b3, amounts): variance_usd (all 70 rows) | D39: Posted eligible with budget | F39: 0 | G39: 0 | H39: 0 | J39: 0.01 | K39: PASS | L39: max |SQL - reference| = 5.59e-09; null-pattern mismatches 0 | N39: =IF(AND(ISNUMBER(F39),ISNUMBER(G39)),ABS(G39-F39),"") -> 0 | O39: =IF(AND(ISNUMBER(N39),ISNUMBER(J39)),IF(N39<=J39,"PASS","FAIL"),"n/a") -> PASS
A40: F_C1.keys | B40: Independent financial recomputation vs SQL | C40: Forecast error by section (c1): same key set (rows only in one side) | D40: Posted eligible with forecast (54,851) | E40: outer join on scenario,section | F40: 0 | G40: 0 | H40: 0 | J40: 0 | K40: PASS | N40: =IF(AND(ISNUMBER(F40),ISNUMBER(G40)),ABS(G40-F40),"") -> 0 | O40: =IF(AND(ISNUMBER(N40),ISNUMBER(J40)),IF(N40<=J40,"PASS","FAIL"),"n/a") -> PASS
...

Sheet Reference_headline
A1: Independent reference: headline (Posted eligible, scale-adjusted, USD)
A2: revenue = REVENUE section; cost = COGS + PEOPLE + OPEX; result proxy = revenue - cost (not EBITDA).
A3: metric | B3: value
A4: revenue | B4: 2.02649e+08
A5: cost_cogs_people_opex | B5: 1.7632976e+08
A6: result_proxy | B6: 26319246
A7: rows | B7: 58340

Sheet Reference_GP
A1: Independent reference: gross profit S1 / S2 / S3
A3: rowset | B3: treatment | C3: period | D3: rows_in_scope | E3: revenue_usd | F3: cogs_usd | G3: gross_profit_usd | H3: gross_margin_pct
A4: ROWS_ALL | B4: GP_S1_SIGNED_AS_RECORDED | C4: 2023 | D4: 15092 | E4: 61295631 | F4: 28820262 | G4: 32475369 | H4: 0.5298154
A5: ROWS_ALL | B5: GP_S1_SIGNED_AS_RECORDED | C5: 2024 | D5: 14971 | E5: 70362584 | F5: 30243513 | G5: 40119070 | H5: 0.5701762
A6: ROWS_ALL | B6: GP_S1_SIGNED_AS_RECORDED | C6: 2025 | D6: 14948 | E6: 70990788 | F6: 33744243 | G6: 37246545 | H6: 0.5246673
A7: ROWS_ALL | B7: GP_S1_SIGNED_AS_RECORDED | C7: ALL YEARS | D7: 45011 | E7: 2.02649e+08 | F7: 92808018 | G7: 1.0984098e+08 | H7: 0.54202578
A8: ROWS_ALL | B8: GP_S2_DISCOUNT_ABS | C8: 2023 | D8: 15092 | E8: 57208113 | F8: 28820262 | G8: 28387851 | H8: 0.49622072
A9: ROWS_ALL | B9: GP_S2_DISCOUNT_ABS | C9: 2024 | D9: 14971 | E9: 66280235 | F9: 30243513 | G9: 36036722 | H9: 0.54370239
A10: ROWS_ALL | B10: GP_S2_DISCOUNT_ABS | C10: 2025 | D10: 14948 | E10: 66312284 | F10: 33744243 | G10: 32568041 | H10: 0.49113134
A11: ROWS_ALL | B11: GP_S2_DISCOUNT_ABS | C11: ALL YEARS | D11: 45011 | E11: 1.8980063e+08 | F11: 92808018 | G11: 96992615 | H11: 0.51102366
A12: ROWS_ALL | B12: GP_S3_EXCL_DISCOUNT | C12: 2023 | D12: 15092 | E12: 61961255 | F12: 28820262 | G12: 33140994 | H12: 0.5348664
A13: ROWS_ALL | B13: GP_S3_EXCL_DISCOUNT | C13: 2024 | D13: 14971 | E13: 71288869 | F13: 30243513 | G13: 41045355 | H13: 0.57576107
A14: ROWS_ALL | B14: GP_S3_EXCL_DISCOUNT | C14: 2025 | D14: 14948 | E14: 71932361 | F14: 33744243 | G14: 38188118 | H14: 0.53088926
A15: ROWS_ALL | B15: GP_S3_EXCL_DISCOUNT | C15: ALL YEARS | D15: 45011 | E15: 2.0518249e+08 | F15: 92808018 | G15: 1.1237447e+08 | H15: 0.5476806
... A27: ROWS_ALL_NON_NEGATIVE | B27: GP_S3_EXCL_DISCOUNT | C27: ALL YEARS | D27: 26895 | E27: 1.6711147e+08 | F27: 84317375 | G27: 82794099 | H27: 0.49544234

Sheet Reference_CostCentre
A1: Independent reference: people + opex by cost centre
A3: cc | B3: rows | C3: abs_usd | D3: signed_usd
A4: (blank) | B4: 598 | C4: 5761461.1 | D4: 4380482.4
A5: CC110 | B5: 613 | C5: 10327568 | D5: 6917045.5
A6: CC210 | B6: 2051 | C6: 20018762 | D6: 14768890
A7: CC240 | B7: 1351 | C7: 9841493.3 | D7: 7155579.3
A8: CC310 | B8: 1355 | C8: 9334274.2 | D8: 6548033.7
A9: CC410 | B9: 1978 | C9: 20287905 | D9: 14920508
A10: CC510 | B10: 2043 | C10: 20117761 | D10: 14679087
A11: CC610 | B11: 1941 | C11: 19921936 | D11: 14152113

Sheet Reference_Status
A1: Independent reference: journal status diagnostic (any-status P&L population, 136,330 lines)
A3: status | B3: lines | C3: abs_actual_usd
A4: Posted | B4: 58340 | C4: 5.0544435e+08
A5: Pending | B5: 19777 | C5: 1.7049955e+08
A6: Rejected | B6: 19467 | C6: 1.7093226e+08
A7: (blank) | B7: 19444 | C7: 1.6983345e+08
A8: Parked | B8: 19302 | C8: 1.7081047e+08
